Workbook

Sheet Summary
A1: BANK OF GHANA DAILY INTERBANK FX RATES
A2: For the month of July 2026 | D2: 50
A3: .
A4: Details | D4: Direct Quote (HCY to FCY) | J4: Indirect Quote (FCY to HCY)
D5: GHS/USD | F5: GHS/EUR | H5: GHS/GBP | J5: USD/GHS | L5: EUR/GHS | N5: USD/EUR | P5: EUR/USD | R5: GBP/USD
A6: Date | B6: Pairs Code | D6: Average | F6: Average | J6: Average | L6: Average | N6: Average | P6: Average | R6: Average
A7: =+'01-07'!A2:B2 -> 46204 | B7: GHS:USD_EUR_GBP | D7: =+'01-07'!E5 -> 11.35 | F7: =+'01-07'!E16 -> 12.9225 | H7: =+'01-07'!E6 -> 15.08245 | J7: =IF(D7=0," ",1/D7) -> 0.088105727 | L7: =IF(F7=0," ",1/F7) -> 0.077384407 | N7: =IF(F7=0," ",D7/F7) -> 0.87831302 | P7: =IF(D7=0," ",F7/D7) -> 1.1385463 | R7: =IF(D7=0," ",H7/D7) -> 1.3288502
A8: =+'02-07'!A2:B2 -> 46205 | B8: GHS:USD_EUR_GBP | D8: =+'02-07'!E5 -> 11.3895 | F8: =+'02-07'!E16 -> 13.02825 | H8: =+'02-07'!E6 -> 15.2124 | J8: =IF(D8=0," ",1/D8) -> 0.087800167 | L8: =IF(F8=0," ",1/F8) -> 0.07675628 | N8: =IF(F8=0," ",D8/F8) -> 0.87421565 | P8: =IF(D8=0," ",F8/D8) -> 1.1438825 | R8: =IF(D8=0," ",H8/D8) -> 1.3356513
A9: =+'03-06'!A2:B2 -> 46206 | B9: GHS:USD_EUR_GBP | D9: =+'03-06'!E5 -> 0 | F9: =+'03-06'!E16 -> 0 | H9: =+'03-06'!E6 -> 0 | J9: =IF(D9=0," ",1/D9) | L9: =IF(F9=0," ",1/F9) | N9: =IF(F9=0," ",D9/F9) | P9: =IF(D9=0," ",F9/D9) | R9: =IF(D9=0," ",H9/D9)
A10: =+'06-07'!A2:B2 -> 46209 | B10: GHS:USD_EUR_GBP | D10: =+'06-07'!E5 -> 11.39 | F10: =+'06-07'!E16 -> 13.01595 | H10: =+'06-07'!E6 -> 15.2267 | J10: =IF(D10=0," ",1/D10) -> 0.087796313 | L10: =IF(F10=0," ",1/F10) -> 0.076828814 | N10: =IF(F10=0," ",D10/F10) -> 0.87508019 | P10: =IF(D10=0," ",F10/D10) -> 1.1427524 | R10: =IF(D10=0," ",H10/D10) -> 1.3368481
A11: =+'07-07'!A2:B2 -> 46210 | B11: GHS:USD_EUR_GBP | D11: =+'07-07'!E5 -> 11.427 | F11: =+'07-07'!E16 -> 13.0518 | H11: =+'07-07'!E6 -> 15.2785 | J11: =IF(D11=0," ",1/D11) -> 0.087512033 | L11: =IF(F11=0," ",1/F11) -> 0.076617785 | N11: =IF(F11=0," ",D11/F11) -> 0.87551142 | P11: =IF(D11=0," ",F11/D11) -> 1.1421896 | R11: =IF(D11=0," ",H11/D11) -> 1.3370526
A13: =+'08-07'!A2:B2 -> 46211 | B13: GHS:USD_EUR_GBP | D13: =+'08-07'!E5 -> 11.44 | F13: =+'08-07'!E16 -> 13.0398 | H13: =+'08-07'!E6 -> 15.28785 | I13: 0 | J13: =IF(D13=0," ",1/D13) -> 0.087412587 | L13: =IF(F13=0," ",1/F13) -> 0.076688293 | N13: =IF(F13=0," ",D13/F13) -> 0.87731407 | P13: =IF(D13=0," ",F13/D13) -> 1.1398427 | R13: =IF(D13=0," ",H13/D13) -> 1.3363505
A14: =+'09-07'!A2:B2 -> 46212 | B14: GHS:USD_EUR_GBP | D14: =+'09-07'!E5 -> 11.4635 | F14: =+'09-07'!E16 -> 13.10015 | H14: =+'09-07'!E6 -> 15.3783 | J14: =IF(D14=0," ",1/D14) -> 0.087233393 | L14: =IF(F14=0," ",1/F14) -> 0.076335004 | N14: =IF(F14=0," ",D14/F14) -> 0.87506632 | P14: =IF(D14=0," ",F14/D14) -> 1.1427705 | R14: =IF(D14=0," ",H14/D14) -> 1.3415013
A15: =+'10-07'!A2:B2 -> 46213 | B15: GHS:USD_EUR_GBP | D15: =+'10-07'!E5 -> 11.48 | F15: =+'10-07'!E16 -> 13.1318 | H15: =+'10-07'!E6 -> 15.4056 | J15: =IF(D15=0," ",1/D15) -> 0.087108014 | L15: =IF(F15=0," ",1/F15) -> 0.076151023 | N15: =IF(F15=0," ",D15/F15) -> 0.87421374 | P15: =IF(D15=0," ",F15/D15) -> 1.143885 | R15: =IF(D15=0," ",H15/D15) -> 1.3419512
A16: =+'13-07'!A2:B2 -> 46216 | B16: GHS:USD_EUR_GBP | D16: =+'13-07'!E5 -> 11.49 | F16: =+'13-07'!E16 -> 13.0827 | H16: =+'13-07'!E6 -> 15.35125 | J16: =IF(D16=0," ",1/D16) -> 0.087032202 | L16: =IF(F16=0," ",1/F16) -> 0.076436821 | N16: =IF(F16=0," ",D16/F16) -> 0.87825907 | P16: =IF(D16=0," ",F16/D16) -> 1.1386162 | R16: =IF(D16=0," ",H16/D16) -> 1.3360531
A17: =+'14-07'!A2:B2 -> 46217 | B17: GHS:USD_EUR_GBP | D17: =+'14-07'!E5 -> 11.516 | F17: =+'14-07'!E16 -> 13.16335 | H17: =+'14-07'!E6 -> 15.413 | J17: =IF(D17=0," ",1/D17) -> 0.086835707 | L17: =IF(F17=0," ",1/F17) -> 0.075968503 | N17: =IF(F17=0," ",D17/F17) -> 0.87485329 | P17: =IF(D17=0," ",F17/D17) -> 1.1430488 | R17: =IF(D17=0," ",H17/D17) -> 1.3383987
A18: =+'15-07'!A2:B2 -> 46218 | B18: GHS:USD_EUR_GBP | D18: =+'15-07'!E5 -> 11.525 | F18: =+'15-07'!E16 -> 13.18235 | H18: =+'15-07'!E6 -> 15.58355 | J18: =IF(D18=0," ",1/D18) -> 0.086767896 | L18: =IF(F18=0," ",1/F18) -> 0.075859008 | N18: =IF(F18=0," ",D18/F18) -> 0.87427507 | P18: =IF(D18=0," ",F18/D18) -> 1.1438048 | R18: =IF(D18=0," ",H18/D18) -> 1.3521518
A19: =+'16-07'!A2:B2 -> 46219 | B19: GHS:USD_EUR_GBP | D19: =+'16-07'!E5 -> 0 | F19: =+'16-07'!E16 -> 0 | H19: =+'16-07'!E6 -> 0 | J19: =IF(D19=0," ",1/D19) | L19: =IF(F19=0," ",1/F19) | N19: =IF(F19=0," ",D19/F19) | P19: =IF(D19=0," ",F19/D19) | R19: =IF(D19=0," ",H19/D19)
A20: =+'17-07'!A2:B2 -> 46220 | B20: GHS:USD_EUR_GBP | D20: =+'17-07'!E5 -> 0 | F20: =+'17-07'!E16 -> 0 | H20: =+'17-07'!E6 -> 0 | J20: =IF(D20=0," ",1/D20) | L20: =IF(F20=0," ",1/F20) | N20: =IF(F20=0," ",D20/F20) | P20: =IF(D20=0," ",F20/D20) | R20: =IF(D20=0," ",H20/D20)
A21: =+'20-07'!A2:B2 -> 46223 | B21: GHS:USD_EUR_GBP | D21: =+'20-07'!E5 -> 0 | F21: =+'20-07'!E16 -> 0 | H21: =+'20-07'!E6 -> 0 | J21: =IF(D21=0," ",1/D21) | L21: =IF(F21=0," ",1/F21) | N21: =IF(F21=0," ",D21/F21) | P21: =IF(D21=0," ",F21/D21) | R21: =IF(D21=0," ",H21/D21)
A22: =+'21-07'!A2:B2 -> 46224 | B22: GHS:USD_EUR_GBP | D22: =+'21-07'!E5 -> 0 | F22: =+'21-07'!E16 -> 0 | H22: =+'21-07'!E6 -> 0 | J22: =IF(D22=0," ",1/D22) | L22: =IF(F22=0," ",1/F22) | N22: =IF(F22=0," ",D22/F22) | P22: =IF(D22=0," ",F22/D22) | R22: =IF(D22=0," ",H22/D22)
A23: =+'22-06'!A2:B2 -> 46225 | B23: GHS:USD_EUR_GBP | D23: =+'22-06'!E5 -> 0 | F23: =+'22-06'!E16 -> 0 | H23: =+'22-06'!E6 -> 0 | J23: =IF(D23=0," ",1/D23) | L23: =IF(F23=0," ",1/F23) | N23: =IF(F23=0," ",D23/F23) | P23: =IF(D23=0," ",F23/D23) | R23: =IF(D23=0," ",H23/D23)
A24: =+'23-07'!A2:B2 -> 46226 | B24: GHS:USD_EUR_GBP | D24: =+'23-07'!E5 -> 0 | F24: =+'23-07'!E16 -> 0 | H24: =+'23-07'!E6 -> 0 | J24: =IF(D24=0," ",1/D24) | L24: =IF(F24=0," ",1/F24) | N24: =IF(F24=0," ",D24/F24) | P24: =IF(D24=0," ",F24/D24) | R24: =IF(D24=0," ",H24/D24)
A25: ='24-07'!A2 -> 46227 | B25: GHS:USD_EUR_GBP | D25: =+'24-07'!E5 -> 0 | F25: =+'24-07'!E16 -> 0 | H25: =+'24-07'!E6 -> 0 | J25: =IF(D25=0," ",1/D25) | L25: =IF(F25=0," ",1/F25) | N25: =IF(F25=0," ",D25/F25) | P25: =IF(D25=0," ",F25/D25) | R25: =IF(D25=0," ",H25/D25)
A26: ='27-07'!A2 -> 46230 | B26: GHS:USD_EUR_GBP | D26: ='27-07'!E5 -> 0 | F26: ='27-07'!E16 -> 0 | H26: ='27-07'!E6 -> 0 | J26: =IF(D26=0," ",1/D26) | L26: =IF(F26=0," ",1/F26) | N26: =IF(F26=0," ",D26/F26) | P26: =IF(D26=0," ",F26/D26) | R26: =IF(D26=0," ",H26/D26)
A27: ='28-07'!A2 -> 46231 | B27: GHS:USD_EUR_GBP | D27: ='28-07'!E5 -> 0 | F27: ='28-07'!E16 -> 0 | H27: ='28-07'!E6 -> 0 | J27: =IF(D27=0," ",1/D27) | L27: =IF(F27=0," ",1/F27) | N27: =IF(F27=0," ",D27/F27) | P27: =IF(D27=0," ",F27/D27) | R27: =IF(D27=0," ",H27/D27)
A28: ='29-07 '!A2 -> 46232 | B28: GHS:USD_EUR_GBP | D28: ='29-07 '!E5 -> 0 | F28: ='29-07 '!E16 -> 0 | H28: ='29-07 '!E6 -> 0 | J28: =IF(D28=0," ",1/D28) | L28: =IF(F28=0," ",1/F28) | N28: =IF(F28=0," ",D28/F28) | P28: =IF(D28=0," ",F28/D28) | R28: =IF(D28=0," ",H28/D28)
A29: ='30-07'!A2 -> 46233 | B29: GHS:USD_EUR_GBP | D29: ='30-07'!E5 -> 0 | F29: ='30-07'!E16 -> 0 | H29: ='30-07'!E6 -> 0 | J29: =IF(D29=0," ",1/D29) | L29: =IF(F29=0," ",1/F29) | N29: =IF(F29=0," ",D29/F29) | P29: =IF(D29=0," ",F29/D29) | R29: =IF(D29=0," ",H29/D29)
A30: ='31-07'!A2 -> 46234 | B30: GHS:USD_EUR_GBP | D30: {=_xlfn.ANCHORARRAY('31-07'!E5)} -> 0
J35: =IF(D35=0," ",1/D35)
A36: Prepared by: | H36: Reviewed by:
A37: Accountant………………………………………………………. | H37: Finance Supervisor…………………………………………………
J38: =IF(D38=0," ",1/D38) | L38: =IF(F38=0," ",1/F38)
J39: =IF(D39=0," ",1/D39) | L39: =IF(F39=0," ",1/F39)
J40: =IF(D40=0," ",1/D40) | L40: =IF(F40=0," ",1/F40)
J41: =IF(D41=0," ",1/D41) | L41: =IF(F41=0," ",1/F41)
J42: =IF(D42=0," ",1/D42) | L42: =IF(F42=0," ",1/F42)

Sheet 01-07
A1: BANK OF GHANA DAILY INTERBANK FX RATES
A2: 46204
E3: USD-GHS | G3: GHS-USD
A4: Currency | B4: Pairs Code | C4: Buying | D4: Selling | E4: Average | G4: Average
A5: US Dollar | B5: USDGHS | C5: 11.3443 | D5: 11.3557 | E5: =SUM(C5:D5)/2 -> 11.35 | G5: =IF(E5=0," ",1/E5) -> 0.088105727
A6: Pound Sterling | B6: GBPGHS | C6: 15.0743 | D6: 15.0906 | E6: =SUM(C6:D6)/2 -> 15.08245 | G6: =IF(E6=0," ",1/E6) -> 0.066302225
A7: Swiss Franc | B7: CHFGHS | C7: 14.0357 | D7: 14.0495 | E7: =SUM(C7:D7)/2 -> 14.0426 | G7: =IF(E7=0," ",1/E7) -> 0.071211884
A8: Australian Dollar | B8: AUDGHS | C8: 7.8326 | D8: 7.8411 | E8: =SUM(C8:D8)/2 -> 7.83685 | G8: =IF(E8=0," ",1/E8) -> 0.12760229
A9: Canadian Dollar | B9: CADGHS | C9: 7.9868 | D9: 7.9946 | E9: =SUM(C9:D9)/2 -> 7.9907 | G9: =IF(E9=0," ",1/E9) -> 0.12514548
A10: Danish Krone | B10: DKKGHS | C10: 1.728 | D10: 1.7297 | E10: =SUM(C10:D10)/2 -> 1.72885 | G10: =IF(E10=0," ",1/E10) -> 0.57841918
A11: Japanese yen | B11: JPYGHS | C11: 0.0699 | D11: 0.0699 | E11: =SUM(C11:D11)/2 -> 0.0699 | G11: =IF(E11=0," ",1/E11) -> 14.306152
A12: New Zealand Dollar | B12: NZDGHS | C12: 6.4428 | D12: 6.4512 | E12: =SUM(C12:D12)/2 -> 6.447 | G12: =IF(E12=0," ",1/E12) -> 0.1551109
A13: Norwegian Krone | B13: NOKGHS | C13: 1.1463 | D13: 1.1471 | E13: =SUM(C13:D13)/2 -> 1.1467 | G13: =IF(E13=0," ",1/E13) -> 0.87206767
A14: Swedish Krona | B14: SEKGHS | C14: 1.1675 | D14: 1.1685 | E14: =SUM(C14:D14)/2 -> 1.168 | G14: =IF(E14=0," ",1/E14) -> 0.85616438
A15: South African Rand | B15: ZARGHS | C15: 0.692 | D15: 0.6925 | E15: =SUM(C15:D15)/2 -> 0.69225 | G15: =IF(E15=0," ",1/E15) -> 1.4445648
A16: Euro | B16: EURGHS | C16: 12.9161 | D16: 12.9289 | E16: =SUM(C16:D16)/2 -> 12.9225 | G16: =IF(E16=0," ",1/E16) -> 0.077384407
A17: Yuan Renminbi | B17: CNYGHS | C17: 1.6706 | D17: 1.6717 | E17: =SUM(C17:D17)/2 -> 1.67115 | G17: =IF(E17=0," ",1/E17) -> 0.59839033
A18: BCEAO | B18: GHSXOF | C18: 50.7357 | D18: 50.786 | E18: =IF(G18=0," ",1/G18) -> 0.019700222 | G18: =SUM(C18:D18)/2 -> 50.76085
A19: Dalasi | B19: GHSGMD | C19: 6.4041 | D19: 6.482 | E19: =IF(G19=0," ",1/G19) -> 0.155206 | G19: =SUM(C19:D19)/2 -> 6.44305
A20: Ouguiya | B20: GHSMRO | C20: 31.4537 | D20: 31.5419 | E20: =IF(G20=0," ",1/G20) -> 0.031748249 | G20: =SUM(C20:D20)/2 -> 31.4978
A21: Naira | B21: GHSNGN | C21: 120.748 | D21: 121.2326 | E21: =IF(G21=0," ",1/G21) -> 0.0082651254 | G21: =SUM(C21:D21)/2 -> 120.9903
A22: Leone | B22: GHSSLL | C22: 2103.9648 | D22: 2159.9525 | E22: =IF(G22=0," ",1/G22) -> 0.00046905225 | G22: =SUM(C22:D22)/2 -> 2131.9587
A23: Ecowas | B23: WAUGHS | C23: 0.0132 | D23: 0.0132 | E23: =SUM(C23:D23)/2 -> 0.0132 | G23: =IF(E23=0," ",1/E23) -> 75.757576

Sheet 02-07
A1: BANK OF GHANA DAILY INTERBANK FX RATES
A2: =('01-07'!A2)+1 -> 46205
E3: USD-GHS | G3: GHS-USD
A4: Currency | B4: Pairs Code | C4: Buying | D4: Selling | E4: Average | G4: Average
A5: US Dollar | B5: USDGHS | C5: 11.3838 | D5: 11.3952 | E5: =SUM(C5:D5)/2 -> 11.3895 | G5: =IF(E5=0," ",1/E5) -> 0.087800167
A6: Pound Sterling | B6: GBPGHS | C6: 15.2042 | D6: 15.2206 | E6: =SUM(C6:D6)/2 -> 15.2124 | G6: =IF(E6=0," ",1/E6) -> 0.065735847
A7: Swiss Franc | B7: CHFGHS | C7: 14.1857 | D7: 14.1983 | E7: =SUM(C7:D7)/2 -> 14.192 | G7: =IF(E7=0," ",1/E7) -> 0.070462232
A8: Australian Dollar | B8: AUDGHS | C8: 7.8834 | D8: 7.8919 | E8: =SUM(C8:D8)/2 -> 7.88765 | G8: =IF(E8=0," ",1/E8) -> 0.12678047
A9: Canadian Dollar | B9: CADGHS | C9: 8.028 | D9: 8.0358 | E9: =SUM(C9:D9)/2 -> 8.0319 | G9: =IF(E9=0," ",1/E9) -> 0.12450354
A10: Danish Krone | B10: DKKGHS | C10: 1.7421 | D10: 1.7438 | E10: =SUM(C10:D10)/2 -> 1.74295 | G10: =IF(E10=0," ",1/E10) -> 0.57373992
A11: Japanese yen | B11: JPYGHS | C11: 0.0707 | D11: 0.0708 | E11: =SUM(C11:D11)/2 -> 0.07075 | G11: =IF(E11=0," ",1/E11) -> 14.134276
A12: New Zealand Dollar | B12: NZDGHS | C12: 6.4892 | D12: 6.4977 | E12: =SUM(C12:D12)/2 -> 6.49345 | G12: =IF(E12=0," ",1/E12) -> 0.15400134
A13: Norwegian Krone | B13: NOKGHS | C13: 1.1571 | D13: 1.1578 | E13: =SUM(C13:D13)/2 -> 1.15745 | G13: =IF(E13=0," ",1/E13) -> 0.86396821
A14: Swedish Krona | B14: SEKGHS | C14: 1.1781 | D14: 1.179 | E14: =SUM(C14:D14)/2 -> 1.17855 | G14: =IF(E14=0," ",1/E14) -> 0.84850028
A15: South African Rand | B15: ZARGHS | C15: 0.7001 | D15: 0.7005 | E15: =SUM(C15:D15)/2 -> 0.7003 | G15: =IF(E15=0," ",1/E15) -> 1.4279594
A16: Euro | B16: EURGHS | C16: 13.0218 | D16: 13.0347 | E16: =SUM(C16:D16)/2 -> 13.02825 | G16: =IF(E16=0," ",1/E16) -> 0.07675628
A17: Yuan Renminbi | B17: CNYGHS | C17: 1.6779 | D17: 1.6793 | E17: =SUM(C17:D17)/2 -> 1.6786 | G17: =IF(E17=0," ",1/E17) -> 0.59573454
A18: BCEAO | B18: GHSXOF | C18: 50.3239 | D18: 50.3738 | E18: =IF(G18=0," ",1/G18) -> 0.019861427 | G18: =SUM(C18:D18)/2 -> 50.34885
A19: Dalasi | B19: GHSGMD | C19: 6.3819 | D19: 6.4041 | E19: =IF(G19=0," ",1/G19) -> 0.15642109 | G19: =SUM(C19:D19)/2 -> 6.393
A20: Ouguiya | B20: GHSMRO | C20: 31.3447 | D20: 31.4325 | E20: =IF(G20=0," ",1/G20) -> 0.0318587 | G20: =SUM(C20:D20)/2 -> 31.3886
A21: Naira | B21: GHSNGN | C21: 120.3573 | D21: 120.4451 | E21: =IF(G21=0," ",1/G21) -> 0.0083055651 | G21: =SUM(C21:D21)/2 -> 120.4012
A22: Leone | B22: GHSSLL | C22: 2091.8565 | D22: 2145.4314 | E22: =IF(G22=0," ",1/G22) -> 0.00047200003 | G22: =SUM(C22:D22)/2 -> 2118.6439
A23: Ecowas | B23: WAUGHS | C23: 0.0131 | D23: 0.0131 | E23: =SUM(C23:D23)/2 -> 0.0131 | G23: =IF(E23=0," ",1/E23) -> 76.335878

Sheet 03-06
A1: BANK OF GHANA DAILY INTERBANK FX RATES
A2: =('02-07'!A2)+1 -> 46206 | B2: 00-01-1900
E3: USD-GHS | G3: GHS-USD
A4: Currency | B4: Pairs Code | C4: Buying | D4: Selling | E4: Average | G4: Average
E5: =SUM(C5:D5)/2 -> 0 | G5: =IF(E5=0," ",1/E5)
E6: =SUM(C6:D6)/2 -> 0 | G6: =IF(E6=0," ",1/E6)
E7: =SUM(C7:D7)/2 -> 0 | G7: =IF(E7=0," ",1/E7)
E8: =SUM(C8:D8)/2 -> 0 | G8: =IF(E8=0," ",1/E8)
E9: =SUM(C9:D9)/2 -> 0 | G9: =IF(E9=0," ",1/E9)
E10: =SUM(C10:D10)/2 -> 0 | G10: =IF(E10=0," ",1/E10)
E11: =SUM(C11:D11)/2 -> 0 | G11: =IF(E11=0," ",1/E11)
E12: =SUM(C12:D12)/2 -> 0 | G12: =IF(E12=0," ",1/E12)
E13: =SUM(C13:D13)/2 -> 0 | G13: =IF(E13=0," ",1/E13)
E14: =SUM(C14:D14)/2 -> 0 | G14: =IF(E14=0," ",1/E14)
E15: =SUM(C15:D15)/2 -> 0 | G15: =IF(E15=0," ",1/E15)
E16: =SUM(C16:D16)/2 -> 0 | G16: =IF(E16=0," ",1/E16)
E17: =SUM(C17:D17)/2 -> 0 | G17: =IF(E17=0," ",1/E17)
E18: =IF(G18=0," ",1/G18) | G18: =SUM(C18:D18)/2 -> 0
E19: =IF(G19=0," ",1/G19) | G19: =SUM(C19:D19)/2 -> 0
E20: =IF(G20=0," ",1/G20) | G20: =SUM(C20:D20)/2 -> 0
E21: =IF(G21=0," ",1/G21) | G21: =SUM(C21:D21)/2 -> 0
E22: =IF(G22=0," ",1/G22) | G22: =SUM(C22:D22)/2 -> 0
E23: =SUM(C23:D23)/2 -> 0 | G23: =IF(E23=0," ",1/E23)

Sheet 06-07
A1: BANK OF GHANA DAILY INTERBANK FX RATES
A2: =('03-06'!A2)+3 -> 46209
E3: USD-GHS | G3: GHS-USD
A4: Currency | B4: Pairs Code | C4: Buying | D4: Selling | E4: Average | G4: Average
A5: US Dollar | B5: USDGHS | C5: 11.3843 | D5: 11.3957 | E5: =SUM(C5:D5)/2 -> 11.39 | G5: =IF(E5=0," ",1/E5) -> 0.087796313
A6: Pound Sterling | B6: GBPGHS | C6: 15.2185 | D6: 15.2349 | E6: =SUM(C6:D6)/2 -> 15.2267 | G6: =IF(E6=0," ",1/E6) -> 0.065674112
A7: Swiss Franc | B7: CHFGHS | C7: 14.1226 | D7: 14.1352 | E7: =SUM(C7:D7)/2 -> 14.1289 | G7: =IF(E7=0," ",1/E7) -> 0.070776918
A8: Australian Dollar | B8: AUDGHS | C8: 7.906 | D8: 7.9145 | E8: =SUM(C8:D8)/2 -> 7.91025 | G8: =IF(E8=0," ",1/E8) -> 0.12641825
A9: Canadian Dollar | B9: CADGHS | C9: 8.0089 | D9: 8.0171 | E9: =SUM(C9:D9)/2 -> 8.013 | G9: =IF(E9=0," ",1/E9) -> 0.1247972
A10: Danish Krone | B10: DKKGHS | C10: 1.7406 | D10: 1.7422 | E10: =SUM(C10:D10)/2 -> 1.7414 | G10: =IF(E10=0," ",1/E10) -> 0.5742506
A11: Japanese yen | B11: JPYGHS | C11: 0.0701 | D11: 0.0702 | E11: =SUM(C11:D11)/2 -> 0.07015 | G11: =IF(E11=0," ",1/E11) -> 14.255167
A12: New Zealand Dollar | B12: NZDGHS | C12: 6.4785 | D12: 6.487 | E12: =SUM(C12:D12)/2 -> 6.48275 | G12: =IF(E12=0," ",1/E12) -> 0.15425552
A13: Norwegian Krone | B13: NOKGHS | C13: 1.1595 | D13: 1.1603 | E13: =SUM(C13:D13)/2 -> 1.1599 | G13: =IF(E13=0," ",1/E13) -> 0.86214329
A14: Swedish Krona | B14: SEKGHS | C14: 1.1806 | D14: 1.1815 | E14: =SUM(C14:D14)/2 -> 1.18105 | G14: =IF(E14=0," ",1/E14) -> 0.8467042
A15: South African Rand | B15: ZARGHS | C15: 0.7018 | D15: 0.7023 | E15: =SUM(C15:D15)/2 -> 0.70205 | G15: =IF(E15=0," ",1/E15) -> 1.4244
A16: Euro | B16: EURGHS | C16: 13.0095 | D16: 13.0224 | E16: =SUM(C16:D16)/2 -> 13.01595 | G16: =IF(E16=0," ",1/E16) -> 0.076828814
A17: Yuan Renminbi | B17: CNYGHS | C17: 1.6758 | D17: 1.6772 | E17: =SUM(C17:D17)/2 -> 1.6765 | G17: =IF(E17=0," ",1/E17) -> 0.59648076
A18: BCEAO | B18: GHSXOF | C18: 50.3714 | D18: 50.4214 | E18: =IF(G18=0," ",1/G18) -> 0.019842687 | G18: =SUM(C18:D18)/2 -> 50.3964
A19: Dalasi | B19: GHSGMD | C19: 6.3685 | D19: 6.4632 | E19: =IF(G19=0," ",1/G19) -> 0.15586399 | G19: =SUM(C19:D19)/2 -> 6.41585
A20: Ouguiya | B20: GHSMRO | C20: 31.3433 | D20: 31.4311 | E20: =IF(G20=0," ",1/G20) -> 0.031860121 | G20: =SUM(C20:D20)/2 -> 31.3872
A21: Naira | B21: GHSNGN | C21: 120.1124 | D21: 120.3933 | E21: =IF(G21=0," ",1/G21) -> 0.0083158112 | G21: =SUM(C21:D21)/2 -> 120.25285
A22: Leone | B22: GHSSLL | C22: 2089.8341 | D22: 2144.3944 | E22: =IF(G22=0," ",1/G22) -> 0.00047234107 | G22: =SUM(C22:D22)/2 -> 2117.1143
A23: Ecowas | B23: WAUGHS | C23: 0.0131 | D23: 0.0131 | E23: =SUM(C23:D23)/2 -> 0.0131 | G23: =IF(E23=0," ",1/E23) -> 76.335878

Sheet 07-07
A1: BANK OF GHANA DAILY INTERBANK FX RATES
A2: =('06-07'!A2)+1 -> 46210
E3: USD-GHS | G3: GHS-USD
A4: Currency | B4: Pairs Code | C4: Buying | D4: Selling | E4: Average | G4: Average
A5: US Dollar | B5: USDGHS | C5: 11.4213 | D5: 11.4327 | E5: =SUM(C5:D5)/2 -> 11.427 | G5: =IF(E5=0," ",1/E5) -> 0.087512033
A6: Pound Sterling | B6: GBPGHS | C6: 15.2703 | D6: 15.2867 | E6: =SUM(C6:D6)/2 -> 15.2785 | G6: =IF(E6=0," ",1/E6) -> 0.065451451
A7: Swiss Franc | B7: CHFGHS | C7: 14.1549 | D7: 14.1675 | E7: =SUM(C7:D7)/2 -> 14.1612 | G7: =IF(E7=0," ",1/E7) -> 0.070615485
A8: Australian Dollar | B8: AUDGHS | C8: 7.9207 | D8: 7.9307 | E8: =SUM(C8:D8)/2 -> 7.9257 | G8: =IF(E8=0," ",1/E8) -> 0.12617182
A9: Canadian Dollar | B9: CADGHS | C9: 8.0488 | D9: 8.0566 | E9: =SUM(C9:D9)/2 -> 8.0527 | G9: =IF(E9=0," ",1/E9) -> 0.12418195
A10: Danish Krone | B10: DKKGHS | C10: 1.7453 | D10: 1.7469 | E10: =SUM(C10:D10)/2 -> 1.7461 | G10: =IF(E10=0," ",1/E10) -> 0.57270489
A11: Japanese yen | B11: JPYGHS | C11: 0.0705 | D11: 0.0706 | E11: =SUM(C11:D11)/2 -> 0.07055 | G11: =IF(E11=0," ",1/E11) -> 14.174344
A12: New Zealand Dollar | B12: NZDGHS | C12: 6.4914 | D12: 6.5014 | E12: =SUM(C12:D12)/2 -> 6.4964 | G12: =IF(E12=0," ",1/E12) -> 0.15393141
A13: Norwegian Krone | B13: NOKGHS | C13: 1.166 | D13: 1.1668 | E13: =SUM(C13:D13)/2 -> 1.1664 | G13: =IF(E13=0," ",1/E13) -> 0.85733882
A14: Swedish Krona | B14: SEKGHS | C14: 1.1807 | D14: 1.1816 | E14: =SUM(C14:D14)/2 -> 1.18115 | G14: =IF(E14=0," ",1/E14) -> 0.84663252
A15: South African Rand | B15: ZARGHS | C15: 0.7031 | D15: 0.7036 | E15: =SUM(C15:D15)/2 -> 0.70335 | G15: =IF(E15=0," ",1/E15) -> 1.4217673
A16: Euro | B16: EURGHS | C16: 13.0459 | D16: 13.0577 | E16: =SUM(C16:D16)/2 -> 13.0518 | G16: =IF(E16=0," ",1/E16) -> 0.076617785
A17: Yuan Renminbi | B17: CNYGHS | C17: 1.681 | D17: 1.6819 | E17: =SUM(C17:D17)/2 -> 1.68145 | G17: =IF(E17=0," ",1/E17) -> 0.59472479
A18: BCEAO | B18: GHSXOF | C18: 50.2353 | D18: 50.2807 | E18: =IF(G18=0," ",1/G18) -> 0.01989733 | G18: =SUM(C18:D18)/2 -> 50.258
A19: Dalasi | B19: GHSGMD | C19: 6.3643 | D19: 6.3656 | E19: =IF(G19=0," ",1/G19) -> 0.15711043 | G19: =SUM(C19:D19)/2 -> 6.36495
A20: Ouguiya | B20: GHSMRO | C20: 31.2418 | D20: 31.3293 | E20: =IF(G20=0," ",1/G20) -> 0.031963638 | G20: =SUM(C20:D20)/2 -> 31.28555
A21: Naira | B21: GHSNGN | C21: 119.9904 | D21: 120.1426 | E21: =IF(G21=0," ",1/G21) -> 0.0083287178 | G21: =SUM(C21:D21)/2 -> 120.0665
A22: Leone | B22: GHSSLL | C22: 2083.0752 | D22: 2134.4185 | E22: =IF(G22=0," ",1/G22) -> 0.00047421529 | G22: =SUM(C22:D22)/2 -> 2108.7469
A23: Ecowas | B23: WAUGHS | C23: 0.0131 | D23: 0.0131 | E23: =SUM(C23:D23)/2 -> 0.0131 | G23: =IF(E23=0," ",1/E23) -> 76.335878

Sheet 09-01
A1: BANK OF GHANA DAILY INTERBANK FX RATES
A2: =('07-07'!A2)+1 -> 46211
E3: USD-GHS | G3: GHS-USD
A4: Currency | B4: Pairs Code | C4: Buying | D4: Selling | E4: Average | G4: Average
A5: US Dollar | E5: =SUM(C5:D5)/2 -> 0 | G5: =IF(E5=0," ",1/E5)
A6: Pound Sterling | E6: =SUM(C6:D6)/2 -> 0 | G6: =IF(E6=0," ",1/E6)
A7: Swiss Franc | E7: =SUM(C7:D7)/2 -> 0 | G7: =IF(E7=0," ",1/E7)
A8: Australian Dollar | E8: =SUM(C8:D8)/2 -> 0 | G8: =IF(E8=0," ",1/E8)
A9: Canadian Dollar | E9: =SUM(C9:D9)/2 -> 0 | G9: =IF(E9=0," ",1/E9)
A10: Danish Krone | E10: =SUM(C10:D10)/2 -> 0 | G10: =IF(E10=0," ",1/E10)
A11: Japanese yen | E11: =SUM(C11:D11)/2 -> 0 | G11: =IF(E11=0," ",1/E11)
A12: New Zealand Dollar | E12: =SUM(C12:D12)/2 -> 0 | G12: =IF(E12=0," ",1/E12)
A13: Norwegian Krone | E13: =SUM(C13:D13)/2 -> 0 | G13: =IF(E13=0," ",1/E13)
A14: Swedish Krona | E14: =SUM(C14:D14)/2 -> 0 | G14: =IF(E14=0," ",1/E14)
A15: South African Rand | E15: =SUM(C15:D15)/2 -> 0 | G15: =IF(E15=0," ",1/E15)
A16: Euro | E16: =SUM(C16:D16)/2 -> 0 | G16: =IF(E16=0," ",1/E16)
A17: Yuan Renminbi | E17: =SUM(C17:D17)/2 -> 0 | G17: =IF(E17=0," ",1/E17)
A18: BCEAO | E18: =IF(G18=0," ",1/G18) | G18: =SUM(C18:D18)/2 -> 0
A19: Dalasi | E19: =IF(G19=0," ",1/G19) | G19: =SUM(C19:D19)/2 -> 0
A20: Ouguiya | E20: =IF(G20=0," ",1/G20) | G20: =SUM(C20:D20)/2 -> 0
A21: Naira | E21: =IF(G21=0," ",1/G21) | G21: =SUM(C21:D21)/2 -> 0
A22: Leone | E22: =IF(G22=0," ",1/G22) | G22: =SUM(C22:D22)/2 -> 0
A23: Ecowas | E23: =SUM(C23:D23)/2 -> 0 | G23: =IF(E23=0," ",1/E23)

Sheet 08-07
A1: BANK OF GHANA DAILY INTERBANK FX RATES
A2: =('07-07'!A2)+1 -> 46211
E3: USD-GHS | G3: GHS-USD
A4: Currency | B4: Pairs Code | C4: Buying | D4: Selling | E4: Average | G4: Average
A5: US Dollar | B5: USDGHS | C5: 11.4343 | D5: 11.4457 | E5: =SUM(C5:D5)/2 -> 11.44 | G5: =IF(E5=0," ",1/E5) -> 0.087412587
A6: Pound Sterling | B6: GBPGHS | C6: 15.2796 | D6: 15.2961 | E6: =SUM(C6:D6)/2 -> 15.28785 | G6: =IF(E6=0," ",1/E6) -> 0.065411421
A7: Swiss Franc | B7: CHFGHS | C7: 14.1112 | D7: 14.1251 | E7: =SUM(C7:D7)/2 -> 14.11815 | G7: =IF(E7=0," ",1/E7) -> 0.07083081
A8: Australian Dollar | B8: AUDGHS | C8: 7.9026 | D8: 7.9127 | E8: =SUM(C8:D8)/2 -> 7.90765 | G8: =IF(E8=0," ",1/E8) -> 0.12645982
A9: Canadian Dollar | B9: CADGHS | C9: 8.0614 | D9: 8.0692 | E9: =SUM(C9:D9)/2 -> 8.0653 | G9: =IF(E9=0," ",1/E9) -> 0.12398795
A10: Danish Krone | B10: DKKGHS | C10: 1.7435 | D10: 1.7452 | E10: =SUM(C10:D10)/2 -> 1.74435 | G10: =IF(E10=0," ",1/E10) -> 0.57327945
A11: Japanese yen | B11: JPYGHS | C11: 0.0703 | D11: 0.0704 | E11: =SUM(C11:D11)/2 -> 0.07035 | G11: =IF(E11=0," ",1/E11) -> 14.214641
A12: New Zealand Dollar | B12: NZDGHS | C12: 6.5 | D12: 6.5085 | E12: =SUM(C12:D12)/2 -> 6.50425 | G12: =IF(E12=0," ",1/E12) -> 0.15374563
A13: Norwegian Krone | B13: NOKGHS | C13: 1.1664 | D13: 1.1672 | E13: =SUM(C13:D13)/2 -> 1.1668 | G13: =IF(E13=0," ",1/E13) -> 0.85704491
A14: Swedish Krona | B14: SEKGHS | C14: 1.1744 | D14: 1.1754 | E14: =SUM(C14:D14)/2 -> 1.1749 | G14: =IF(E14=0," ",1/E14) -> 0.85113627
A15: South African Rand | B15: ZARGHS | C15: 0.6947 | D15: 0.6951 | E15: =SUM(C15:D15)/2 -> 0.6949 | G15: =IF(E15=0," ",1/E15) -> 1.439056
A16: Euro | B16: EURGHS | C16: 13.0339 | D16: 13.0457 | E16: =SUM(C16:D16)/2 -> 13.0398 | G16: =IF(E16=0," ",1/E16) -> 0.076688293
A17: Yuan Renminbi | B17: CNYGHS | C17: 1.6807 | D17: 1.6814 | E17: =SUM(C17:D17)/2 -> 1.68105 | G17: =IF(E17=0," ",1/E17) -> 0.5948663
A18: BCEAO | B18: GHSXOF | C18: 50.2815 | D18: 50.327 | E18: =IF(G18=0," ",1/G18) -> 0.019879036 | G18: =SUM(C18:D18)/2 -> 50.30425
A19: Dalasi | B19: GHSGMD | C19: 6.3571 | D19: 6.4314 | E19: =IF(G19=0," ",1/G19) -> 0.15639051 | G19: =SUM(C19:D19)/2 -> 6.39425
A20: Ouguiya | B20: GHSMRO | C20: 31.2063 | D20: 31.2937 | E20: =IF(G20=0," ",1/G20) -> 0.032 | G20: =SUM(C20:D20)/2 -> 31.25
A21: Naira | B21: GHSNGN | C21: 120.4642 | D21: 120.5743 | E21: =IF(G21=0," ",1/G21) -> 0.0082974297 | G21: =SUM(C21:D21)/2 -> 120.51925
A22: Leone | B22: GHSSLL | C22: 2078.6444 | D22: 2131.993 | E22: =IF(G22=0," ",1/G22) -> 0.00047498747 | G22: =SUM(C22:D22)/2 -> 2105.3187
A23: Ecowas | B23: WAUGHS | C23: 0.013 | D23: 0.013 | E23: =SUM(C23:D23)/2 -> 0.013 | G23: =IF(E23=0," ",1/E23) -> 76.923077

Sheet 09-07
A1: BANK OF GHANA DAILY INTERBANK FX RATES
A2: =('07-07'!A2)+2 -> 46212
E3: USD-GHS | G3: GHS-USD
A4: Currency | B4: Pairs Code | C4: Buying | D4: Selling | E4: Average | G4: Average
A5: US Dollar | B5: USDGHS | C5: 11.4578 | D5: 11.4692 | E5: =SUM(C5:D5)/2 -> 11.4635 | G5: =IF(E5=0," ",1/E5) -> 0.087233393
A6: Pound Sterling | B6: GBPGHS | C6: 15.3706 | D6: 15.386 | E6: =SUM(C6:D6)/2 -> 15.3783 | G6: =IF(E6=0," ",1/E6) -> 0.065026693
A7: Swiss Franc | B7: CHFGHS | C7: 14.1913 | D7: 14.2042 | E7: =SUM(C7:D7)/2 -> 14.19775 | G7: =IF(E7=0," ",1/E7) -> 0.070433695
A8: Australian Dollar | B8: AUDGHS | C8: 7.9481 | D8: 7.9561 | E8: =SUM(C8:D8)/2 -> 7.9521 | G8: =IF(E8=0," ",1/E8) -> 0.12575295
A9: Canadian Dollar | B9: CADGHS | C9: 8.0804 | D9: 8.0877 | E9: =SUM(C9:D9)/2 -> 8.08405 | G9: =IF(E9=0," ",1/E9) -> 0.12370037
A10: Danish Krone | B10: DKKGHS | C10: 1.7517 | D10: 1.7532 | E10: =SUM(C10:D10)/2 -> 1.75245 | G10: =IF(E10=0," ",1/E10) -> 0.57062969
A11: Japanese yen | B11: JPYGHS | C11: 0.0706 | D11: 0.0706 | E11: =SUM(C11:D11)/2 -> 0.0706 | G11: =IF(E11=0," ",1/E11) -> 14.164306
A12: New Zealand Dollar | B12: NZDGHS | C12: 6.5679 | D12: 6.576 | E12: =SUM(C12:D12)/2 -> 6.57195 | G12: =IF(E12=0," ",1/E12) -> 0.15216184
A13: Norwegian Krone | B13: NOKGHS | C13: 1.1732 | D13: 1.174 | E13: =SUM(C13:D13)/2 -> 1.1736 | G13: =IF(E13=0," ",1/E13) -> 0.85207907
A14: Swedish Krona | B14: SEKGHS | C14: 1.1833 | D14: 1.1842 | E14: =SUM(C14:D14)/2 -> 1.18375 | G14: =IF(E14=0," ",1/E14) -> 0.84477297
A15: South African Rand | B15: ZARGHS | C15: 0.7002 | D15: 0.7006 | E15: =SUM(C15:D15)/2 -> 0.7004 | G15: =IF(E15=0," ",1/E15) -> 1.4277556
A16: Euro | B16: EURGHS | C16: 13.0947 | D16: 13.1056 | E16: =SUM(C16:D16)/2 -> 13.10015 | G16: =IF(E16=0," ",1/E16) -> 0.076335004
A17: Yuan Renminbi | B17: CNYGHS | C17: 1.6866 | D17: 1.6882 | E17: =SUM(C17:D17)/2 -> 1.6874 | G17: =IF(E17=0," ",1/E17) -> 0.59262771
A18: BCEAO | B18: GHSXOF | C18: 50.0517 | D18: 50.0933 | E18: =IF(G18=0," ",1/G18) -> 0.019971042 | G18: =SUM(C18:D18)/2 -> 50.0725
A19: Dalasi | B19: GHSGMD | C19: 6.3605 | D19: 6.4182 | E19: =IF(G19=0," ",1/G19) -> 0.15651044 | G19: =SUM(C19:D19)/2 -> 6.38935
A20: Ouguiya | B20: GHSMRO | C20: 31.1423 | D20: 31.2296 | E20: =IF(G20=0," ",1/G20) -> 0.032065722 | G20: =SUM(C20:D20)/2 -> 31.18595
A21: Naira | B21: GHSNGN | C21: 120.0724 | D21: 120.3786 | E21: =IF(G21=0," ",1/G21) -> 0.008317703 | G21: =SUM(C21:D21)/2 -> 120.2255
A22: Leone | B22: GHSSLL | C22: 2074.1746 | D22: 2127.6225 | E22: =IF(G22=0," ",1/G22) -> 0.00047598681 | G22: =SUM(C22:D22)/2 -> 2100.8985
A23: Ecowas | B23: WAUGHS | C23: 0.013 | D23: 0.013 | E23: =SUM(C23:D23)/2 -> 0.013 | G23: =IF(E23=0," ",1/E23) -> 76.923077

Sheet 10-07
A1: BANK OF GHANA DAILY INTERBANK FX RATES
A2: =('07-07'!A2)+3 -> 46213
E3: USD-GHS | G3: GHS-USD
A4: Currency | B4: Pairs Code | C4: Buying | D4: Selling | E4: Average | G4: Average
A5: US Dollar | B5: USDGHS | C5: 11.4743 | D5: 11.4857 | E5: =SUM(C5:D5)/2 -> 11.48 | G5: =IF(E5=0," ",1/E5) -> 0.087108014
A6: Pound Sterling | B6: GBPGHS | C6: 15.3973 | D6: 15.4139 | E6: =SUM(C6:D6)/2 -> 15.4056 | G6: =IF(E6=0," ",1/E6) -> 0.064911461
A7: Swiss Franc | B7: CHFGHS | C7: 14.2304 | D7: 14.2444 | E7: =SUM(C7:D7)/2 -> 14.2374 | G7: =IF(E7=0," ",1/E7) -> 0.070237543
A8: Australian Dollar | B8: AUDGHS | C8: 7.9897 | D8: 7.9998 | E8: =SUM(C8:D8)/2 -> 7.99475 | G8: =IF(E8=0," ",1/E8) -> 0.12508209
A9: Canadian Dollar | B9: CADGHS | C9: 8.1261 | D9: 8.134 | E9: =SUM(C9:D9)/2 -> 8.13005 | G9: =IF(E9=0," ",1/E9) -> 0.12300047
A10: Danish Krone | B10: DKKGHS | C10: 1.756 | D10: 1.7576 | E10: =SUM(C10:D10)/2 -> 1.7568 | G10: =IF(E10=0," ",1/E10) -> 0.56921676
A11: Japanese yen | B11: JPYGHS | C11: 0.0711 | D11: 0.0712 | E11: =SUM(C11:D11)/2 -> 0.07115 | G11: =IF(E11=0," ",1/E11) -> 14.054814
A12: New Zealand Dollar | B12: NZDGHS | C12: 6.627 | D12: 6.6357 | E12: =SUM(C12:D12)/2 -> 6.63135 | G12: =IF(E12=0," ",1/E12) -> 0.15079886
A13: Norwegian Krone | B13: NOKGHS | C13: 1.1759 | D13: 1.1767 | E13: =SUM(C13:D13)/2 -> 1.1763 | G13: =IF(E13=0," ",1/E13) -> 0.85012327
A14: Swedish Krona | B14: SEKGHS | C14: 1.1911 | D14: 1.192 | E14: =SUM(C14:D14)/2 -> 1.19155 | G14: =IF(E14=0," ",1/E14) -> 0.839243
A15: South African Rand | B15: ZARGHS | C15: 0.7044 | D15: 0.7048 | E15: =SUM(C15:D15)/2 -> 0.7046 | G15: =IF(E15=0," ",1/E15) -> 1.419245
A16: Euro | B16: EURGHS | C16: 13.1253 | D16: 13.1383 | E16: =SUM(C16:D16)/2 -> 13.1318 | G16: =IF(E16=0," ",1/E16) -> 0.076151023
A17: Yuan Renminbi | B17: CNYGHS | C17: 1.6939 | D17: 1.6949 | E17: =SUM(C17:D17)/2 -> 1.6944 | G17: =IF(E17=0," ",1/E17) -> 0.59017941
A18: BCEAO | B18: GHSXOF | C18: 49.9271 | D18: 49.9765 | E18: =IF(G18=0," ",1/G18) -> 0.020019299 | G18: =SUM(C18:D18)/2 -> 49.9518
A19: Dalasi | B19: GHSGMD | C19: 6.3142 | D19: 6.3197 | E19: =IF(G19=0," ",1/G19) -> 0.15830424 | G19: =SUM(C19:D19)/2 -> 6.31695
A20: Ouguiya | B20: GHSMRO | C20: 31.0976 | D20: 31.1847 | E20: =IF(G20=0," ",1/G20) -> 0.032111852 | G20: =SUM(C20:D20)/2 -> 31.14115
A21: Naira | B21: GHSNGN | C21: 120.1141 | D21: 120.2012 | E21: =IF(G21=0," ",1/G21) -> 0.0083223998 | G21: =SUM(C21:D21)/2 -> 120.15765
A22: Leone | B22: GHSSLL | C22: 2069.975 | D22: 2124.5645 | E22: =IF(G22=0," ",1/G22) -> 0.00047681039 | G22: =SUM(C22:D22)/2 -> 2097.2697
A23: Ecowas | B23: WAUGHS | C23: 0.0129 | D23: 0.0129 | E23: =SUM(C23:D23)/2 -> 0.0129 | G23: =IF(E23=0," ",1/E23) -> 77.51938

Sheet 13-07
A1: BANK OF GHANA DAILY INTERBANK FX RATES
A2: =('07-07'!A2)+6 -> 46216
E3: USD-GHS | G3: GHS-USD
A4: Currency | B4: Pairs Code | C4: Buying | D4: Selling | E4: Average | G4: Average
A5: US Dollar | B5: USDGHS | C5: 11.4843 | D5: 11.4957 | E5: =SUM(C5:D5)/2 -> 11.49 | G5: =IF(E5=0," ",1/E5) -> 0.087032202
A6: Pound Sterling | B6: GBPGHS | C6: 15.343 | D6: 15.3595 | E6: =SUM(C6:D6)/2 -> 15.35125 | G6: =IF(E6=0," ",1/E6) -> 0.065141275
A7: Swiss Franc | B7: CHFGHS | C7: 14.115 | D7: 14.1275 | E7: =SUM(C7:D7)/2 -> 14.12125 | G7: =IF(E7=0," ",1/E7) -> 0.070815261
A8: Australian Dollar | B8: AUDGHS | C8: 7.9461 | D8: 7.9562 | E8: =SUM(C8:D8)/2 -> 7.95115 | G8: =IF(E8=0," ",1/E8) -> 0.12576797
A9: Canadian Dollar | B9: CADGHS | C9: 8.1163 | D9: 8.1241 | E9: =SUM(C9:D9)/2 -> 8.1202 | G9: =IF(E9=0," ",1/E9) -> 0.12314968
A10: Danish Krone | B10: DKKGHS | C10: 1.7492 | D10: 1.7509 | E10: =SUM(C10:D10)/2 -> 1.75005 | G10: =IF(E10=0," ",1/E10) -> 0.57141225
A11: Japanese yen | B11: JPYGHS | C11: 0.0707 | D11: 0.0708 | E11: =SUM(C11:D11)/2 -> 0.07075 | G11: =IF(E11=0," ",1/E11) -> 14.134276
A12: New Zealand Dollar | B12: NZDGHS | C12: 6.6082 | D12: 6.6153 | E12: =SUM(C12:D12)/2 -> 6.61175 | G12: =IF(E12=0," ",1/E12) -> 0.15124589
A13: Norwegian Krone | B13: NOKGHS | C13: 1.1735 | D13: 1.1743 | E13: =SUM(C13:D13)/2 -> 1.1739 | G13: =IF(E13=0," ",1/E13) -> 0.85186132
A14: Swedish Krona | B14: SEKGHS | C14: 1.1835 | D14: 1.1844 | E14: =SUM(C14:D14)/2 -> 1.18395 | G14: =IF(E14=0," ",1/E14) -> 0.84463026
A15: South African Rand | B15: ZARGHS | C15: 0.6988 | D15: 0.6992 | E15: =SUM(C15:D15)/2 -> 0.699 | G15: =IF(E15=0," ",1/E15) -> 1.4306152
A16: Euro | B16: EURGHS | C16: 13.0768 | D16: 13.0886 | E16: =SUM(C16:D16)/2 -> 13.0827 | G16: =IF(E16=0," ",1/E16) -> 0.076436821
A17: Yuan Renminbi | B17: CNYGHS | C17: 1.6943 | D17: 1.6952 | E17: =SUM(C17:D17)/2 -> 1.69475 | G17: =IF(E17=0," ",1/E17) -> 0.59005753
A18: BCEAO | B18: GHSXOF | C18: 50.1167 | D18: 50.1619 | E18: =IF(G18=0," ",1/G18) -> 0.019944435 | G18: =SUM(C18:D18)/2 -> 50.1393
A19: Dalasi | B19: GHSGMD | C19: 6.3304 | D19: 6.403 | E19: =IF(G19=0," ",1/G19) -> 0.15706724 | G19: =SUM(C19:D19)/2 -> 6.3667
A20: Ouguiya | B20: GHSMRO | C20: 31.0705 | D20: 31.1575 | E20: =IF(G20=0," ",1/G20) -> 0.032139873 | G20: =SUM(C20:D20)/2 -> 31.114
A21: Naira | B21: GHSNGN | C21: 120.0975 | D21: 120.1854 | E21: =IF(G21=0," ",1/G21) -> 0.008323522 | G21: =SUM(C21:D21)/2 -> 120.14145
A22: Leone | B22: GHSSLL | C22: 2068.9468 | D22: 2122.7154 | E22: =IF(G22=0," ",1/G22) -> 0.00047713769 | G22: =SUM(C22:D22)/2 -> 2095.8311
A23: Ecowas | B23: WAUGHS | C23: 0.0129 | D23: 0.0129 | E23: =SUM(C23:D23)/2 -> 0.0129 | G23: =IF(E23=0," ",1/E23) -> 77.51938

Sheet 14-07
A1: BANK OF GHANA DAILY INTERBANK FX RATES
A2: =('07-07'!A2)+7 -> 46217
E3: USD-GHS | G3: GHS-USD
A4: Currency | B4: Pairs Code | C4: Buying | D4: Selling | E4: Average | G4: Average
A5: US Dollar | B5: USDGHS | C5: 11.5102 | D5: 11.5218 | E5: =SUM(C5:D5)/2 -> 11.516 | G5: =IF(E5=0," ",1/E5) -> 0.086835707
A6: Pound Sterling | B6: GBPGHS | C6: 15.4053 | D6: 15.4207 | E6: =SUM(C6:D6)/2 -> 15.413 | G6: =IF(E6=0," ",1/E6) -> 0.064880296
A7: Swiss Franc | B7: CHFGHS | C7: 14.2312 | D7: 14.2442 | E7: =SUM(C7:D7)/2 -> 14.2377 | G7: =IF(E7=0," ",1/E7) -> 0.070236063
A8: Australian Dollar | B8: AUDGHS | C8: 8.0277 | D8: 8.0357 | E8: =SUM(C8:D8)/2 -> 8.0317 | G8: =IF(E8=0," ",1/E8) -> 0.12450664
A9: Canadian Dollar | B9: CADGHS | C9: 8.1834 | D9: 8.1907 | E9: =SUM(C9:D9)/2 -> 8.18705 | G9: =IF(E9=0," ",1/E9) -> 0.12214412
A10: Danish Krone | B10: DKKGHS | C10: 1.76 | D10: 1.7616 | E10: =SUM(C10:D10)/2 -> 1.7608 | G10: =IF(E10=0," ",1/E10) -> 0.56792367
A11: Japanese yen | B11: JPYGHS | C11: 0.071 | D11: 0.0711 | E11: =SUM(C11:D11)/2 -> 0.07105 | G11: =IF(E11=0," ",1/E11) -> 14.074595
A12: New Zealand Dollar | B12: NZDGHS | C12: 6.6844 | D12: 6.6926 | E12: =SUM(C12:D12)/2 -> 6.6885 | G12: =IF(E12=0," ",1/E12) -> 0.14951035
A13: Norwegian Krone | B13: NOKGHS | C13: 1.1888 | D13: 1.1896 | E13: =SUM(C13:D13)/2 -> 1.1892 | G13: =IF(E13=0," ",1/E13) -> 0.84090145
A14: Swedish Krona | B14: SEKGHS | C14: 1.1922 | D14: 1.1931 | E14: =SUM(C14:D14)/2 -> 1.19265 | G14: =IF(E14=0," ",1/E14) -> 0.83846896
A15: South African Rand | B15: ZARGHS | C15: 0.703 | D15: 0.7033 | E15: =SUM(C15:D15)/2 -> 0.70315 | G15: =IF(E15=0," ",1/E15) -> 1.4221717
A16: Euro | B16: EURGHS | C16: 13.1579 | D16: 13.1688 | E16: =SUM(C16:D16)/2 -> 13.16335 | G16: =IF(E16=0," ",1/E16) -> 0.075968503
A17: Yuan Renminbi | B17: CNYGHS | C17: 1.7004 | D17: 1.7012 | E17: =SUM(C17:D17)/2 -> 1.7008 | G17: =IF(E17=0," ",1/E17) -> 0.58795861
A18: BCEAO | B18: GHSXOF | C18: 49.8114 | D18: 49.8527 | E18: =IF(G18=0," ",1/G18) -> 0.020067406 | G18: =SUM(C18:D18)/2 -> 49.83205
A19: Dalasi | B19: GHSGMD | C19: 6.3118 | D19: 6.3161 | E19: =IF(G19=0," ",1/G19) -> 0.15837946 | G19: =SUM(C19:D19)/2 -> 6.31395
A20: Ouguiya | B20: GHSMRO | C20: 31.0003 | D20: 31.0872 | E20: =IF(G20=0," ",1/G20) -> 0.032212603 | G20: =SUM(C20:D20)/2 -> 31.04375
A21: Naira | B21: GHSNGN | C21: 119.987 | D21: 120.092 | E21: =IF(G21=0," ",1/G21) -> 0.0083305912 | G21: =SUM(C21:D21)/2 -> 120.0395
A22: Leone | B22: GHSSLL | C22: 2064.2757 | D22: 2119.6596 | E22: =IF(G22=0," ",1/G22) -> 0.00047801886 | G22: =SUM(C22:D22)/2 -> 2091.9677
A23: Ecowas | B23: WAUGHS | C23: 0.0129 | D23: 0.0129 | E23: =SUM(C23:D23)/2 -> 0.0129 | G23: =IF(E23=0," ",1/E23) -> 77.51938

Sheet 15-07
A1: BANK OF GHANA DAILY INTERBANK FX RATES
A2: =('07-07'!A2)+8 -> 46218
E3: USD-GHS | G3: GHS-USD
A4: Currency | B4: Pairs Code | C4: Buying | D4: Selling | E4: Average | G4: Average
A5: US Dollar | B5: USDGHS | C5: 11.5192 | D5: 11.5308 | E5: =SUM(C5:D5)/2 -> 11.525 | G5: =IF(E5=0," ",1/E5) -> 0.086767896
A6: Pound Sterling | B6: GBPGHS | C6: 15.5752 | D6: 15.5919 | E6: =SUM(C6:D6)/2 -> 15.58355 | G6: =IF(E6=0," ",1/E6) -> 0.064170231
A7: Swiss Franc | B7: CHFGHS | C7: 14.276 | D7: 14.2901 | E7: =SUM(C7:D7)/2 -> 14.28305 | G7: =IF(E7=0," ",1/E7) -> 0.070013057
A8: Australian Dollar | B8: AUDGHS | C8: 8.0524 | D8: 8.0626 | E8: =SUM(C8:D8)/2 -> 8.0575 | G8: =IF(E8=0," ",1/E8) -> 0.12410797
A9: Canadian Dollar | B9: CADGHS | C9: 8.1975 | D9: 8.2054 | E9: =SUM(C9:D9)/2 -> 8.20145 | G9: =IF(E9=0," ",1/E9) -> 0.12192966
A10: Danish Krone | B10: DKKGHS | C10: 1.7627 | D10: 1.7643 | E10: =SUM(C10:D10)/2 -> 1.7635 | G10: =IF(E10=0," ",1/E10) -> 0.56705415
A11: Japanese yen | B11: JPYGHS | C11: 0.071 | D11: 0.0711 | E11: =SUM(C11:D11)/2 -> 0.07105 | G11: =IF(E11=0," ",1/E11) -> 14.074595
A12: New Zealand Dollar | B12: NZDGHS | C12: 6.7207 | D12: 6.7295 | E12: =SUM(C12:D12)/2 -> 6.7251 | G12: =IF(E12=0," ",1/E12) -> 0.14869667
A13: Norwegian Krone | B13: NOKGHS | C13: 1.1909 | D13: 1.1917 | E13: =SUM(C13:D13)/2 -> 1.1913 | G13: =IF(E13=0," ",1/E13) -> 0.83941912
A14: Swedish Krona | B14: SEKGHS | C14: 1.1956 | D14: 1.1966 | E14: =SUM(C14:D14)/2 -> 1.1961 | G14: =IF(E14=0," ",1/E14) -> 0.8360505
A15: South African Rand | B15: ZARGHS | C15: 0.7051 | D15: 0.7055 | E15: =SUM(C15:D15)/2 -> 0.7053 | G15: =IF(E15=0," ",1/E15) -> 1.4178364
A16: Euro | B16: EURGHS | C16: 13.1758 | D16: 13.1889 | E16: =SUM(C16:D16)/2 -> 13.18235 | G16: =IF(E16=0," ",1/E16) -> 0.075859008
A17: Yuan Renminbi | B17: CNYGHS | C17: 1.702 | D17: 1.7031 | E17: =SUM(C17:D17)/2 -> 1.70255 | G17: =IF(E17=0," ",1/E17) -> 0.58735426
A18: BCEAO | B18: GHSXOF | C18: 49.7355 | D18: 49.785 | E18: =IF(G18=0," ",1/G18) -> 0.020096362 | G18: =SUM(C18:D18)/2 -> 49.76025
A19: Dalasi | B19: GHSGMD | C19: 6.3204 | D19: 6.397 | E19: =IF(G19=0," ",1/G19) -> 0.15726485 | G19: =SUM(C19:D19)/2 -> 6.3587
A20: Ouguiya | B20: GHSMRO | C20: 30.9761 | D20: 31.0629 | E20: =IF(G20=0," ",1/G20) -> 0.032237786 | G20: =SUM(C20:D20)/2 -> 31.0195
A21: Naira | B21: GHSNGN | C21: 119.8265 | D21: 119.9132 | E21: =IF(G21=0," ",1/G21) -> 0.0083423813 | G21: =SUM(C21:D21)/2 -> 119.86985
A22: Leone | B22: GHSSLL | C22: 2062.6637 | D22: 2118.0043 | E22: =IF(G22=0," ",1/G22) -> 0.00047839245 | G22: =SUM(C22:D22)/2 -> 2090.334
A23: Ecowas | B23: WAUGHS | C23: 0.0128 | D23: 0.0128 | E23: =SUM(C23:D23)/2 -> 0.0128 | G23: =IF(E23=0," ",1/E23) -> 78.125

Sheet 16-07
A1: BANK OF GHANA DAILY INTERBANK FX RATES
A2: =('07-07'!A2)+9 -> 46219
E3: USD-GHS | G3: GHS-USD
A4: Currency | B4: Pairs Code | C4: Buying | D4: Selling | E4: Average | G4: Average
E5: =SUM(C5:D5)/2 -> 0 | G5: =IF(E5=0," ",1/E5)
E6: =SUM(C6:D6)/2 -> 0 | G6: =IF(E6=0," ",1/E6)
E7: =SUM(C7:D7)/2 -> 0 | G7: =IF(E7=0," ",1/E7)
E8: =SUM(C8:D8)/2 -> 0 | G8: =IF(E8=0," ",1/E8)
E9: =SUM(C9:D9)/2 -> 0 | G9: =IF(E9=0," ",1/E9)
E10: =SUM(C10:D10)/2 -> 0 | G10: =IF(E10=0," ",1/E10)
E11: =SUM(C11:D11)/2 -> 0 | G11: =IF(E11=0," ",1/E11)
E12: =SUM(C12:D12)/2 -> 0 | G12: =IF(E12=0," ",1/E12)
E13: =SUM(C13:D13)/2 -> 0 | G13: =IF(E13=0," ",1/E13)
E14: =SUM(C14:D14)/2 -> 0 | G14: =IF(E14=0," ",1/E14)
E15: =SUM(C15:D15)/2 -> 0 | G15: =IF(E15=0," ",1/E15)
E16: =SUM(C16:D16)/2 -> 0 | G16: =IF(E16=0," ",1/E16)
E17: =SUM(C17:D17)/2 -> 0 | G17: =IF(E17=0," ",1/E17)
E18: =IF(G18=0," ",1/G18) | G18: =SUM(C18:D18)/2 -> 0
E19: =IF(G19=0," ",1/G19) | G19: =SUM(C19:D19)/2 -> 0
E20: =IF(G20=0," ",1/G20) | G20: =SUM(C20:D20)/2 -> 0
E21: =IF(G21=0," ",1/G21) | G21: =SUM(C21:D21)/2 -> 0
E22: =IF(G22=0," ",1/G22) | G22: =SUM(C22:D22)/2 -> 0
E23: =SUM(C23:D23)/2 -> 0 | G23: =IF(E23=0," ",1/E23)

Sheet 17-07
A1: BANK OF GHANA DAILY INTERBANK FX RATES
A2: =('07-07'!A2)+10 -> 46220
E3: USD-GHS | G3: GHS-USD
A4: Currency | B4: Pairs Code | C4: Buying | D4: Selling | E4: Average | G4: Average
E5: =SUM(C5:D5)/2 -> 0 | G5: =IF(E5=0," ",1/E5)
E6: =SUM(C6:D6)/2 -> 0 | G6: =IF(E6=0," ",1/E6)
E7: =SUM(C7:D7)/2 -> 0 | G7: =IF(E7=0," ",1/E7)
E8: =SUM(C8:D8)/2 -> 0 | G8: =IF(E8=0," ",1/E8)
E9: =SUM(C9:D9)/2 -> 0 | G9: =IF(E9=0," ",1/E9)
E10: =SUM(C10:D10)/2 -> 0 | G10: =IF(E10=0," ",1/E10)
E11: =SUM(C11:D11)/2 -> 0 | G11: =IF(E11=0," ",1/E11)
E12: =SUM(C12:D12)/2 -> 0 | G12: =IF(E12=0," ",1/E12)
E13: =SUM(C13:D13)/2 -> 0 | G13: =IF(E13=0," ",1/E13)
E14: =SUM(C14:D14)/2 -> 0 | G14: =IF(E14=0," ",1/E14)
E15: =SUM(C15:D15)/2 -> 0 | G15: =IF(E15=0," ",1/E15)
E16: =SUM(C16:D16)/2 -> 0 | G16: =IF(E16=0," ",1/E16)
E17: =SUM(C17:D17)/2 -> 0 | G17: =IF(E17=0," ",1/E17)
E18: =IF(G18=0," ",1/G18) | G18: =SUM(C18:D18)/2 -> 0
E19: =IF(G19=0," ",1/G19) | G19: =SUM(C19:D19)/2 -> 0
E20: =IF(G20=0," ",1/G20) | G20: =SUM(C20:D20)/2 -> 0
E21: =IF(G21=0," ",1/G21) | G21: =SUM(C21:D21)/2 -> 0
E22: =IF(G22=0," ",1/G22) | G22: =SUM(C22:D22)/2 -> 0
E23: =SUM(C23:D23)/2 -> 0 | G23: =IF(E23=0," ",1/E23)

Sheet 20-07
A1: BANK OF GHANA DAILY INTERBANK FX RATES
A2: =('07-07'!A2)+13 -> 46223
E3: USD-GHS | G3: GHS-USD
A4: Currency | B4: Pairs Code | C4: Buying | D4: Selling | E4: Average | G4: Average
E5: =SUM(C5:D5)/2 -> 0 | G5: =IF(E5=0," ",1/E5)
E6: =SUM(C6:D6)/2 -> 0 | G6: =IF(E6=0," ",1/E6)
E7: =SUM(C7:D7)/2 -> 0 | G7: =IF(E7=0," ",1/E7)
E8: =SUM(C8:D8)/2 -> 0 | G8: =IF(E8=0," ",1/E8)
E9: =SUM(C9:D9)/2 -> 0 | G9: =IF(E9=0," ",1/E9)
E10: =SUM(C10:D10)/2 -> 0 | G10: =IF(E10=0," ",1/E10)
E11: =SUM(C11:D11)/2 -> 0 | G11: =IF(E11=0," ",1/E11)
E12: =SUM(C12:D12)/2 -> 0 | G12: =IF(E12=0," ",1/E12)
E13: =SUM(C13:D13)/2 -> 0 | G13: =IF(E13=0," ",1/E13)
E14: =SUM(C14:D14)/2 -> 0 | G14: =IF(E14=0," ",1/E14)
E15: =SUM(C15:D15)/2 -> 0 | G15: =IF(E15=0," ",1/E15)
E16: =SUM(C16:D16)/2 -> 0 | G16: =IF(E16=0," ",1/E16)
E17: =SUM(C17:D17)/2 -> 0 | G17: =IF(E17=0," ",1/E17)
E18: =IF(G18=0," ",1/G18) | G18: =SUM(C18:D18)/2 -> 0
E19: =IF(G19=0," ",1/G19) | G19: =SUM(C19:D19)/2 -> 0
E20: =IF(G20=0," ",1/G20) | G20: =SUM(C20:D20)/2 -> 0
E21: =IF(G21=0," ",1/G21) | G21: =SUM(C21:D21)/2 -> 0
E22: =IF(G22=0," ",1/G22) | G22: =SUM(C22:D22)/2 -> 0
E23: =SUM(C23:D23)/2 -> 0 | G23: =IF(E23=0," ",1/E23)

Sheet 21-07
A1: BANK OF GHANA DAILY INTERBANK FX RATES
A2: =('07-07'!A2)+14 -> 46224
E3: USD-GHS | G3: GHS-USD
A4: Currency | B4: Pairs Code | C4: Buying | D4: Selling | E4: Average | G4: Average
E5: =SUM(C5:D5)/2 -> 0 | G5: =IF(E5=0," ",1/E5)
E6: =SUM(C6:D6)/2 -> 0 | G6: =IF(E6=0," ",1/E6)
E7: =SUM(C7:D7)/2 -> 0 | G7: =IF(E7=0," ",1/E7)
E8: =SUM(C8:D8)/2 -> 0 | G8: =IF(E8=0," ",1/E8)
E9: =SUM(C9:D9)/2 -> 0 | G9: =IF(E9=0," ",1/E9)
E10: =SUM(C10:D10)/2 -> 0 | G10: =IF(E10=0," ",1/E10)
E11: =SUM(C11:D11)/2 -> 0 | G11: =IF(E11=0," ",1/E11)
E12: =SUM(C12:D12)/2 -> 0 | G12: =IF(E12=0," ",1/E12)
E13: =SUM(C13:D13)/2 -> 0 | G13: =IF(E13=0," ",1/E13)
E14: =SUM(C14:D14)/2 -> 0 | G14: =IF(E14=0," ",1/E14)
E15: =SUM(C15:D15)/2 -> 0 | G15: =IF(E15=0," ",1/E15)
E16: =SUM(C16:D16)/2 -> 0 | G16: =IF(E16=0," ",1/E16)
E17: =SUM(C17:D17)/2 -> 0 | G17: =IF(E17=0," ",1/E17)
E18: =IF(G18=0," ",1/G18) | G18: =SUM(C18:D18)/2 -> 0
E19: =IF(G19=0," ",1/G19) | G19: =SUM(C19:D19)/2 -> 0
E20: =IF(G20=0," ",1/G20) | G20: =SUM(C20:D20)/2 -> 0
E21: =IF(G21=0," ",1/G21) | G21: =SUM(C21:D21)/2 -> 0
E22: =IF(G22=0," ",1/G22) | G22: =SUM(C22:D22)/2 -> 0
E23: =SUM(C23:D23)/2 -> 0 | G23: =IF(E23=0," ",1/E23)
E24: =SUM(C24:D24)/2 -> 0 | G24: =IF(E24=0," ",1/E24)

Sheet 22-06
A1: BANK OF GHANA DAILY INTERBANK FX RATES
A2: =('07-07'!A2)+15 -> 46225
E3: USD-GHS | G3: GHS-USD
A4: Currency | B4: Pairs Code | C4: Buying | D4: Selling | E4: Average | G4: Average
E5: =SUM(C5:D5)/2 -> 0 | G5: =IF(E5=0," ",1/E5)
E6: =SUM(C6:D6)/2 -> 0 | G6: =IF(E6=0," ",1/E6)
E7: =SUM(C7:D7)/2 -> 0 | G7: =IF(E7=0," ",1/E7)
E8: =SUM(C8:D8)/2 -> 0 | G8: =IF(E8=0," ",1/E8)
E9: =SUM(C9:D9)/2 -> 0 | G9: =IF(E9=0," ",1/E9)
E10: =SUM(C10:D10)/2 -> 0 | G10: =IF(E10=0," ",1/E10)
E11: =SUM(C11:D11)/2 -> 0 | G11: =IF(E11=0," ",1/E11)
E12: =SUM(C12:D12)/2 -> 0 | G12: =IF(E12=0," ",1/E12)
E13: =SUM(C13:D13)/2 -> 0 | G13: =IF(E13=0," ",1/E13)
E14: =SUM(C14:D14)/2 -> 0 | G14: =IF(E14=0," ",1/E14)
E15: =SUM(C15:D15)/2 -> 0 | G15: =IF(E15=0," ",1/E15)
E16: =SUM(C16:D16)/2 -> 0 | G16: =IF(E16=0," ",1/E16)
E17: =SUM(C17:D17)/2 -> 0 | G17: =IF(E17=0," ",1/E17)
E18: =IF(G18=0," ",1/G18) | G18: =SUM(C18:D18)/2 -> 0
E19: =IF(G19=0," ",1/G19) | G19: =SUM(C19:D19)/2 -> 0
E20: =IF(G20=0," ",1/G20) | G20: =SUM(C20:D20)/2 -> 0
E21: =IF(G21=0," ",1/G21) | G21: =SUM(C21:D21)/2 -> 0
E22: =IF(G22=0," ",1/G22) | G22: =SUM(C22:D22)/2 -> 0
E23: =SUM(C23:D23)/2 -> 0 | G23: =IF(E23=0," ",1/E23)
E24: =SUM(C24:D24)/2 -> 0 | G24: =IF(E24=0," ",1/E24)

Sheet 23-07
A1: BANK OF GHANA DAILY INTERBANK FX RATES
A2: =('07-07'!A2)+16 -> 46226
E3: USD-GHS | G3: GHS-USD
A4: Currency | B4: Pairs Code | C4: Buying | D4: Selling | E4: Average | G4: Average
E5: =SUM(C5:D5)/2 -> 0 | G5: =IF(E5=0," ",1/E5)
E6: =SUM(C6:D6)/2 -> 0 | G6: =IF(E6=0," ",1/E6)
E7: =SUM(C7:D7)/2 -> 0 | G7: =IF(E7=0," ",1/E7)
E8: =SUM(C8:D8)/2 -> 0 | G8: =IF(E8=0," ",1/E8)
E9: =SUM(C9:D9)/2 -> 0 | G9: =IF(E9=0," ",1/E9)
E10: =SUM(C10:D10)/2 -> 0 | G10: =IF(E10=0," ",1/E10)
E11: =SUM(C11:D11)/2 -> 0 | G11: =IF(E11=0," ",1/E11)
E12: =SUM(C12:D12)/2 -> 0 | G12: =IF(E12=0," ",1/E12)
E13: =SUM(C13:D13)/2 -> 0 | G13: =IF(E13=0," ",1/E13)
E14: =SUM(C14:D14)/2 -> 0 | G14: =IF(E14=0," ",1/E14)
E15: =SUM(C15:D15)/2 -> 0 | G15: =IF(E15=0," ",1/E15)
E16: =SUM(C16:D16)/2 -> 0 | G16: =IF(E16=0," ",1/E16)
E17: =SUM(C17:D17)/2 -> 0 | G17: =IF(E17=0," ",1/E17)
E18: =IF(G18=0," ",1/G18) | G18: =SUM(C18:D18)/2 -> 0
E19: =IF(G19=0," ",1/G19) | G19: =SUM(C19:D19)/2 -> 0
E20: =IF(G20=0," ",1/G20) | G20: =SUM(C20:D20)/2 -> 0
E21: =IF(G21=0," ",1/G21) | G21: =SUM(C21:D21)/2 -> 0
E22: =IF(G22=0," ",1/G22) | G22: =SUM(C22:D22)/2 -> 0
E23: =SUM(C23:D23)/2 -> 0 | G23: =IF(E23=0," ",1/E23)
E24: =SUM(C24:D24)/2 -> 0 | G24: =IF(E24=0," ",1/E24)

Sheet 24-07
A1: BANK OF GHANA DAILY INTERBANK FX RATES
A2: =('07-07'!A2)+17 -> 46227
E3: USD-GHS | G3: GHS-USD
A4: Currency | B4: Pairs Code | C4: Buying | D4: Selling | E4: Average | G4: Average
E5: =SUM(C5:D5)/2 -> 0 | G5: =IF(E5=0," ",1/E5)
E6: =SUM(C6:D6)/2 -> 0 | G6: =IF(E6=0," ",1/E6)
E7: =SUM(C7:D7)/2 -> 0 | G7: =IF(E7=0," ",1/E7)
E8: =SUM(C8:D8)/2 -> 0 | G8: =IF(E8=0," ",1/E8)
E9: =SUM(C9:D9)/2 -> 0 | G9: =IF(E9=0," ",1/E9)
E10: =SUM(C10:D10)/2 -> 0 | G10: =IF(E10=0," ",1/E10)
E11: =SUM(C11:D11)/2 -> 0 | G11: =IF(E11=0," ",1/E11)
E12: =SUM(C12:D12)/2 -> 0 | G12: =IF(E12=0," ",1/E12)
E13: =SUM(C13:D13)/2 -> 0 | G13: =IF(E13=0," ",1/E13)
E14: =SUM(C14:D14)/2 -> 0 | G14: =IF(E14=0," ",1/E14)
E15: =SUM(C15:D15)/2 -> 0 | G15: =IF(E15=0," ",1/E15)
E16: =SUM(C16:D16)/2 -> 0 | G16: =IF(E16=0," ",1/E16)
E17: =SUM(C17:D17)/2 -> 0 | G17: =IF(E17=0," ",1/E17)
E18: =IF(G18=0," ",1/G18) | G18: =SUM(C18:D18)/2 -> 0
E19: =IF(G19=0," ",1/G19) | G19: =SUM(C19:D19)/2 -> 0
E20: =IF(G20=0," ",1/G20) | G20: =SUM(C20:D20)/2 -> 0
E21: =IF(G21=0," ",1/G21) | G21: =SUM(C21:D21)/2 -> 0
E22: =IF(G22=0," ",1/G22) | G22: =SUM(C22:D22)/2 -> 0
E23: =SUM(C23:D23)/2 -> 0 | G23: =IF(E23=0," ",1/E23)
E24: =SUM(C24:D24)/2 -> 0 | G24: =IF(E24=0," ",1/E24)

Sheet 27-07
A1: BANK OF GHANA DAILY INTERBANK FX RATES
A2: =('07-07'!A2)+20 -> 46230
E3: USD-GHS | G3: GHS-USD
A4: Currency | B4: Pairs Code | C4: Buying | D4: Selling | E4: Average | G4: Average
E5: =SUM(C5:D5)/2 -> 0 | G5: =IF(E5=0," ",1/E5)
E6: =SUM(C6:D6)/2 -> 0 | G6: =IF(E6=0," ",1/E6)
E7: =SUM(C7:D7)/2 -> 0 | G7: =IF(E7=0," ",1/E7)
E8: =SUM(C8:D8)/2 -> 0 | G8: =IF(E8=0," ",1/E8)
E9: =SUM(C9:D9)/2 -> 0 | G9: =IF(E9=0," ",1/E9)
E10: =SUM(C10:D10)/2 -> 0 | G10: =IF(E10=0," ",1/E10)
E11: =SUM(C11:D11)/2 -> 0 | G11: =IF(E11=0," ",1/E11)
E12: =SUM(C12:D12)/2 -> 0 | G12: =IF(E12=0," ",1/E12)
E13: =SUM(C13:D13)/2 -> 0 | G13: =IF(E13=0," ",1/E13)
E14: =SUM(C14:D14)/2 -> 0 | G14: =IF(E14=0," ",1/E14)
E15: =SUM(C15:D15)/2 -> 0 | G15: =IF(E15=0," ",1/E15)
E16: =SUM(C16:D16)/2 -> 0 | G16: =IF(E16=0," ",1/E16)
E17: =SUM(C17:D17)/2 -> 0 | G17: =IF(E17=0," ",1/E17)
E18: =IF(G18=0," ",1/G18) | G18: =SUM(C18:D18)/2 -> 0
E19: =IF(G19=0," ",1/G19) | G19: =SUM(C19:D19)/2 -> 0
E20: =IF(G20=0," ",1/G20) | G20: =SUM(C20:D20)/2 -> 0
E21: =IF(G21=0," ",1/G21) | G21: =SUM(C21:D21)/2 -> 0
E22: =IF(G22=0," ",1/G22) | G22: =SUM(C22:D22)/2 -> 0
E23: =SUM(C23:D23)/2 -> 0 | G23: =IF(E23=0," ",1/E23)
E24: =SUM(C24:D24)/2 -> 0 | G24: =IF(E24=0," ",1/E24)

Sheet 28-07
A1: BANK OF GHANA DAILY INTERBANK FX RATES
A2: =('07-07'!A2)+21 -> 46231
E3: USD-GHS | G3: GHS-USD
A4: Currency | B4: Pairs Code | C4: Buying | D4: Selling | E4: Average | G4: Average
E5: =SUM(C5:D5)/2 -> 0 | G5: =IF(E5=0," ",1/E5)
E6: =SUM(C6:D6)/2 -> 0 | G6: =IF(E6=0," ",1/E6)
E7: =SUM(C7:D7)/2 -> 0 | G7: =IF(E7=0," ",1/E7)
E8: =SUM(C8:D8)/2 -> 0 | G8: =IF(E8=0," ",1/E8)
E9: =SUM(C9:D9)/2 -> 0 | G9: =IF(E9=0," ",1/E9) | H9: **
E10: =SUM(C10:D10)/2 -> 0 | G10: =IF(E10=0," ",1/E10)
E11: =SUM(C11:D11)/2 -> 0 | G11: =IF(E11=0," ",1/E11)
E12: =SUM(C12:D12)/2 -> 0 | G12: =IF(E12=0," ",1/E12)
E13: =SUM(C13:D13)/2 -> 0 | G13: =IF(E13=0," ",1/E13)
E14: =SUM(C14:D14)/2 -> 0 | G14: =IF(E14=0," ",1/E14)
E15: =SUM(C15:D15)/2 -> 0 | G15: =IF(E15=0," ",1/E15)
E16: =SUM(C16:D16)/2 -> 0 | G16: =IF(E16=0," ",1/E16)
E17: =SUM(C17:D17)/2 -> 0 | G17: =IF(E17=0," ",1/E17)
E18: =IF(G18=0," ",1/G18) | G18: =SUM(C18:D18)/2 -> 0
E19: =IF(G19=0," ",1/G19) | G19: =SUM(C19:D19)/2 -> 0
E20: =IF(G20=0," ",1/G20) | G20: =SUM(C20:D20)/2 -> 0
E21: =IF(G21=0," ",1/G21) | G21: =SUM(C21:D21)/2 -> 0
E22: =IF(G22=0," ",1/G22) | G22: =SUM(C22:D22)/2 -> 0
E23: =SUM(C23:D23)/2 -> 0 | G23: =IF(E23=0," ",1/E23)
E24: =SUM(C24:D24)/2 -> 0 | G24: =IF(E24=0," ",1/E24)

Sheet 29-07 
A1: BANK OF GHANA DAILY INTERBANK FX RATES
A2: =('07-07'!A2)+22 -> 46232
E3: USD-GHS | G3: GHS-USD
A4: Currency | B4: Pairs Code | C4: Buying | D4: Selling | E4: Average | G4: Average
E5: =SUM(C5:D5)/2 -> 0 | G5: =IF(E5=0," ",1/E5)
E6: =SUM(C6:D6)/2 -> 0 | G6: =IF(E6=0," ",1/E6)
E7: =SUM(C7:D7)/2 -> 0 | G7: =IF(E7=0," ",1/E7)
E8: =SUM(C8:D8)/2 -> 0 | G8: =IF(E8=0," ",1/E8)
E9: =SUM(C9:D9)/2 -> 0 | G9: =IF(E9=0," ",1/E9) | H9: **
E10: =SUM(C10:D10)/2 -> 0 | G10: =IF(E10=0," ",1/E10)
E11: =SUM(C11:D11)/2 -> 0 | G11: =IF(E11=0," ",1/E11)
E12: =SUM(C12:D12)/2 -> 0 | G12: =IF(E12=0," ",1/E12)
E13: =SUM(C13:D13)/2 -> 0 | G13: =IF(E13=0," ",1/E13)
E14: =SUM(C14:D14)/2 -> 0 | G14: =IF(E14=0," ",1/E14)
E15: =SUM(C15:D15)/2 -> 0 | G15: =IF(E15=0," ",1/E15)
E16: =SUM(C16:D16)/2 -> 0 | G16: =IF(E16=0," ",1/E16)
E17: =SUM(C17:D17)/2 -> 0 | G17: =IF(E17=0," ",1/E17)
E18: =IF(G18=0," ",1/G18) | G18: =SUM(C18:D18)/2 -> 0
E19: =IF(G19=0," ",1/G19) | G19: =SUM(C19:D19)/2 -> 0
E20: =IF(G20=0," ",1/G20) | G20: =SUM(C20:D20)/2 -> 0
E21: =IF(G21=0," ",1/G21) | G21: =SUM(C21:D21)/2 -> 0
E22: =IF(G22=0," ",1/G22) | G22: =SUM(C22:D22)/2 -> 0
E23: =SUM(C23:D23)/2 -> 0 | G23: =IF(E23=0," ",1/E23)
E24: =SUM(C24:D24)/2 -> 0 | G24: =IF(E24=0," ",1/E24)

Sheet 30-07
A1: BANK OF GHANA DAILY INTERBANK FX RATES
A2: =('07-07'!A2)+23 -> 46233
E3: USD-GHS | G3: GHS-USD
A4: Currency | B4: Pairs Code | C4: Buying | D4: Selling | E4: Average | G4: Average
E5: =SUM(C5:D5)/2 -> 0 | G5: =IF(E5=0," ",1/E5)
E6: =SUM(C6:D6)/2 -> 0 | G6: =IF(E6=0," ",1/E6)
E7: =SUM(C7:D7)/2 -> 0 | G7: =IF(E7=0," ",1/E7)
E8: =SUM(C8:D8)/2 -> 0 | G8: =IF(E8=0," ",1/E8)
E9: =SUM(C9:D9)/2 -> 0 | G9: =IF(E9=0," ",1/E9)
E10: =SUM(C10:D10)/2 -> 0 | G10: =IF(E10=0," ",1/E10)
E11: =SUM(C11:D11)/2 -> 0 | G11: =IF(E11=0," ",1/E11)
E12: =SUM(C12:D12)/2 -> 0 | G12: =IF(E12=0," ",1/E12)
E13: =SUM(C13:D13)/2 -> 0 | G13: =IF(E13=0," ",1/E13)
E14: =SUM(C14:D14)/2 -> 0 | G14: =IF(E14=0," ",1/E14)
E15: =SUM(C15:D15)/2 -> 0 | G15: =IF(E15=0," ",1/E15)
E16: =SUM(C16:D16)/2 -> 0 | G16: =IF(E16=0," ",1/E16)
E17: =SUM(C17:D17)/2 -> 0 | G17: =IF(E17=0," ",1/E17)
E18: =IF(G18=0," ",1/G18) | G18: =SUM(C18:D18)/2 -> 0
E19: =IF(G19=0," ",1/G19) | G19: =SUM(C19:D19)/2 -> 0
E20: =IF(G20=0," ",1/G20) | G20: =SUM(C20:D20)/2 -> 0
E21: =IF(G21=0," ",1/G21) | G21: =SUM(C21:D21)/2 -> 0
E22: =IF(G22=0," ",1/G22) | G22: =SUM(C22:D22)/2 -> 0
E23: =SUM(C23:D23)/2 -> 0 | G23: =IF(E23=0," ",1/E23)
E24: =SUM(C24:D24)/2 -> 0 | G24: =IF(E24=0," ",1/E24)

Sheet 31-07
A1: BANK OF GHANA DAILY INTERBANK FX RATES
A2: =('07-07'!A2)+24 -> 46234
E3: USD-GHS | G3: GHS-USD
A4: Currency | B4: Pairs Code | C4: Buying | D4: Selling | E4: Average | G4: Average
E5: =SUM(C5:D5)/2 -> 0 | G5: =IF(E5=0," ",1/E5)
E6: =SUM(C6:D6)/2 -> 0 | G6: =IF(E6=0," ",1/E6)
E7: =SUM(C7:D7)/2 -> 0 | G7: =IF(E7=0," ",1/E7)
E8: =SUM(C8:D8)/2 -> 0 | G8: =IF(E8=0," ",1/E8)
E9: =SUM(C9:D9)/2 -> 0 | G9: =IF(E9=0," ",1/E9)
E10: =SUM(C10:D10)/2 -> 0 | G10: =IF(E10=0," ",1/E10)
E11: =SUM(C11:D11)/2 -> 0 | G11: =IF(E11=0," ",1/E11)
E12: =SUM(C12:D12)/2 -> 0 | G12: =IF(E12=0," ",1/E12)
E13: =SUM(C13:D13)/2 -> 0 | G13: =IF(E13=0," ",1/E13)
E14: =SUM(C14:D14)/2 -> 0 | G14: =IF(E14=0," ",1/E14)
E15: =SUM(C15:D15)/2 -> 0 | G15: =IF(E15=0," ",1/E15)
E16: =SUM(C16:D16)/2 -> 0 | G16: =IF(E16=0," ",1/E16)
E17: =SUM(C17:D17)/2 -> 0 | G17: =IF(E17=0," ",1/E17)
E18: =IF(G18=0," ",1/G18) | G18: =SUM(C18:D18)/2 -> 0
E19: =IF(G19=0," ",1/G19) | G19: =SUM(C19:D19)/2 -> 0
E20: =IF(G20=0," ",1/G20) | G20: =SUM(C20:D20)/2 -> 0
E21: =IF(G21=0," ",1/G21) | G21: =SUM(C21:D21)/2 -> 0
E22: =IF(G22=0," ",1/G22) | G22: =SUM(C22:D22)/2 -> 0
E23: =SUM(C23:D23)/2 -> 0 | G23: =IF(E23=0," ",1/E23)
E24: =SUM(C24:D24)/2 -> 0 | G24: =IF(E24=0," ",1/E24)

Sheet Sheet1

Sheet 30-01
A1: BANK OF GHANA DAILY INTERBANK FX RATES
A2: =('07-07'!A2)+22 -> 46232
E3: USD-GHS | G3: GHS-USD
A4: Currency | B4: Pairs Code | C4: Buying | D4: Selling | E4: Average | G4: Average
A5: US Dollar | B5: USDGHS | C5: 10.9445 | D5: 10.9555 | E5: =SUM(C5:D5)/2 -> 10.95 | G5: =IF(E5=0," ",1/E5) -> 0.091324201
A6: Pound Sterling | B6: GBPGHS | C6: 15.0159 | D6: 15.032 | E6: =SUM(C6:D6)/2 -> 15.02395 | G6: =IF(E6=0," ",1/E6) -> 0.066560392
A7: Swiss Franc | B7: CHFGHS | C7: 14.2008 | D7: 14.2133 | E7: =SUM(C7:D7)/2 -> 14.20705 | G7: =IF(E7=0," ",1/E7) -> 0.070387589
A8: Australian Dollar | B8: AUDGHS | C8: 7.6581 | D8: 7.6678 | E8: =SUM(C8:D8)/2 -> 7.66295 | G8: =IF(E8=0," ",1/E8) -> 0.13049805
A9: Canadian Dollar | B9: CADGHS | C9: 8.0726 | D9: 8.0804 | E9: =SUM(C9:D9)/2 -> 8.0765 | G9: =IF(E9=0," ",1/E9) -> 0.12381601
A10: Danish Krone | B10: DKKGHS | C10: 1.7415 | D10: 1.7431 | E10: =SUM(C10:D10)/2 -> 1.7423 | G10: =IF(E10=0," ",1/E10) -> 0.57395397
A11: Japanese yen | B11: JPYGHS | C11: 0.0709 | D11: 0.071 | E11: =SUM(C11:D11)/2 -> 0.07095 | G11: =IF(E11=0," ",1/E11) -> 14.094433
A12: New Zealand Dollar | B12: NZDGHS | C12: 6.619 | D12: 6.6261 | E12: =SUM(C12:D12)/2 -> 6.62255 | G12: =IF(E12=0," ",1/E12) -> 0.15099924
A13: Norwegian Krone | B13: NOKGHS | C13: 1.1403 | D13: 1.141 | E13: =SUM(C13:D13)/2 -> 1.14065 | G13: =IF(E13=0," ",1/E13) -> 0.87669311
A14: Swedish Krona | B14: SEKGHS | C14: 1.2345 | D14: 1.2354 | E14: =SUM(C14:D14)/2 -> 1.23495 | G14: =IF(E14=0," ",1/E14) -> 0.80974938
A15: South African Rand | B15: ZARGHS | C15: 0.6838 | D15: 0.6841 | E15: =SUM(C15:D15)/2 -> 0.68395 | G15: =IF(E15=0," ",1/E15) -> 1.4620952
A16: Euro | B16: EURGHS | C16: 13.0053 | D16: 13.017 | E16: =SUM(C16:D16)/2 -> 13.01115 | G16: =IF(E16=0," ",1/E16) -> 0.076857157
A17: Yuan Renminbi | B17: CNYGHS | C17: 1.5741 | D17: 1.5754 | E17: =SUM(C17:D17)/2 -> 1.57475 | G17: =IF(E17=0," ",1/E17) -> 0.63502143
A18: BCEAO | B18: GHSXOF | C18: 50.3923 | D18: 50.4377 | E18: =IF(G18=0," ",1/G18) -> 0.019835366 | G18: =SUM(C18:D18)/2 -> 50.415
A19: Dalasi | B19: GHSGMD | C19: 6.6096 | D19: 6.6098 | E19: =IF(G19=0," ",1/G19) -> 0.1512928 | G19: =SUM(C19:D19)/2 -> 6.6097
A20: Ouguiya | B20: GHSMRO | C20: 32.6027 | D20: 32.6941 | E20: =IF(G20=0," ",1/G20) -> 0.030629372 | G20: =SUM(C20:D20)/2 -> 32.6484
A21: Naira | B21: GHSNGN | C21: 126.7744 | D21: 126.8685 | E21: =IF(G21=0," ",1/G21) -> 0.0078851015 | G21: =SUM(C21:D21)/2 -> 126.82145
A22: Leone | B22: GHSSLL | C22: 2176.3463 | D22: 2209.3379 | E22: =IF(G22=0," ",1/G22) -> 0.00045602919 | G22: =SUM(C22:D22)/2 -> 2192.8421
A23: Ecowas | B23: WAUGHS | C23: 0.0142 | D23: 0.0142 | E23: =SUM(C23:D23)/2 -> 0.0142 | G23: =IF(E23=0," ",1/E23) -> 70.422535
E24: =SUM(C24:D24)/2 -> 0 | G24: =IF(E24=0," ",1/E24)

Sheet 28-01
A1: BANK OF GHANA DAILY INTERBANK FX RATES
A2: =('07-07'!A2)+20 -> 46230
E3: USD-GHS | G3: GHS-USD
A4: Currency | B4: Pairs Code | C4: Buying | D4: Selling | E4: Average | G4: Average
A5: US Dollar | B5: USDGHS | C5: 10.9145 | D5: 10.9255 | E5: =SUM(C5:D5)/2 -> 10.92 | G5: =IF(E5=0," ",1/E5) -> 0.091575092
A6: Pound Sterling | B6: GBPGHS | C6: 15.0359 | D6: 15.052 | E6: =SUM(C6:D6)/2 -> 15.04395 | G6: =IF(E6=0," ",1/E6) -> 0.066471904
A7: Swiss Franc | B7: CHFGHS | C7: 14.1701 | D7: 14.1826 | E7: =SUM(C7:D7)/2 -> 14.17635 | G7: =IF(E7=0," ",1/E7) -> 0.070540019
A8: Australian Dollar | B8: AUDGHS | C8: 7.6307 | D8: 7.6389 | E8: =SUM(C8:D8)/2 -> 7.6348 | G8: =IF(E8=0," ",1/E8) -> 0.1309792
A9: Canadian Dollar | B9: CADGHS | C9: 8.0397 | D9: 8.047 | E9: =SUM(C9:D9)/2 -> 8.04335 | G9: =IF(E9=0," ",1/E9) -> 0.12432631
A10: Danish Krone | B10: DKKGHS | C10: 1.7446 | D10: 1.746 | E10: =SUM(C10:D10)/2 -> 1.7453 | G10: =IF(E10=0," ",1/E10) -> 0.5729674
A11: Japanese yen | B11: JPYGHS | C11: 0.071 | D11: 0.0711 | E11: =SUM(C11:D11)/2 -> 0.07105 | G11: =IF(E11=0," ",1/E11) -> 14.074595
A12: New Zealand Dollar | B12: NZDGHS | C12: 6.5782 | D12: 6.5868 | E12: =SUM(C12:D12)/2 -> 6.5825 | G12: =IF(E12=0," ",1/E12) -> 0.15191796
A13: Norwegian Krone | B13: NOKGHS | C13: 1.1327 | D13: 1.1336 | E13: =SUM(C13:D13)/2 -> 1.13315 | G13: =IF(E13=0," ",1/E13) -> 0.8824957
A14: Swedish Krona | B14: SEKGHS | C14: 1.231 | D14: 1.2319 | E14: =SUM(C14:D14)/2 -> 1.23145 | G14: =IF(E14=0," ",1/E14) -> 0.81205083
A15: South African Rand | B15: ZARGHS | C15: 0.6857 | D15: 0.6859 | E15: =SUM(C15:D15)/2 -> 0.6858 | G15: =IF(E15=0," ",1/E15) -> 1.4581511
A16: Euro | B16: EURGHS | C16: 13.026 | D16: 13.0377 | E16: =SUM(C16:D16)/2 -> 13.03185 | G16: =IF(E16=0," ",1/E16) -> 0.076735076
A17: Yuan Renminbi | B17: CNYGHS | C17: 1.57 | D17: 1.5716 | E17: =SUM(C17:D17)/2 -> 1.5708 | G17: =IF(E17=0," ",1/E17) -> 0.63661828
A18: BCEAO | B18: GHSXOF | C18: 50.3123 | D18: 50.3575 | E18: =IF(G18=0," ",1/G18) -> 0.019866931 | G18: =SUM(C18:D18)/2 -> 50.3349
A19: Dalasi | B19: GHSGMD | C19: 6.6277 | D19: 6.6575 | E19: =IF(G19=0," ",1/G19) -> 0.15054346 | G19: =SUM(C19:D19)/2 -> 6.6426
A20: Ouguiya | B20: GHSMRO | C20: 32.6923 | D20: 32.7839 | E20: =IF(G20=0," ",1/G20) -> 0.03054545 | G20: =SUM(C20:D20)/2 -> 32.7381
A21: Naira | B21: GHSNGN | C21: 127.3114 | D21: 128.2198 | E21: =IF(G21=0," ",1/G21) -> 0.0078268329 | G21: =SUM(C21:D21)/2 -> 127.7656
A22: Leone | B22: GHSSLL | C22: 2186.3049 | D22: 2215.2701 | E22: =IF(G22=0," ",1/G22) -> 0.00045438281 | G22: =SUM(C22:D22)/2 -> 2200.7875
A23: Ecowas | B23: WAUGHS | C23: 0.0143 | D23: 0.0143 | E23: =SUM(C23:D23)/2 -> 0.0143 | G23: =IF(E23=0," ",1/E23) -> 69.93007
E24: =SUM(C24:D24)/2 -> 0 | G24: =IF(E24=0," ",1/E24)

Sheet 30-10
A1: BANK OF GHANA DAILY INTERBANK FX RATES
A2: =('07-07'!A2)+23 -> 46233
E3: USD-GHS | G3: GHS-USD
A4: Currency | B4: Pairs Code | C4: Buying | D4: Selling | E4: Average | G4: Average
E5: =SUM(C5:D5)/2 -> 0 | G5: =IF(E5=0," ",1/E5)
E6: =SUM(C6:D6)/2 -> 0 | G6: =IF(E6=0," ",1/E6)
E7: =SUM(C7:D7)/2 -> 0 | G7: =IF(E7=0," ",1/E7)
E8: =SUM(C8:D8)/2 -> 0 | G8: =IF(E8=0," ",1/E8)
E9: =SUM(C9:D9)/2 -> 0 | G9: =IF(E9=0," ",1/E9)
E10: =SUM(C10:D10)/2 -> 0 | G10: =IF(E10=0," ",1/E10)
E11: =SUM(C11:D11)/2 -> 0 | G11: =IF(E11=0," ",1/E11)
E12: =SUM(C12:D12)/2 -> 0 | G12: =IF(E12=0," ",1/E12)
E13: =SUM(C13:D13)/2 -> 0 | G13: =IF(E13=0," ",1/E13)
E14: =SUM(C14:D14)/2 -> 0 | G14: =IF(E14=0," ",1/E14)
E15: =SUM(C15:D15)/2 -> 0 | G15: =IF(E15=0," ",1/E15)
E16: =SUM(C16:D16)/2 -> 0 | G16: =IF(E16=0," ",1/E16)
E17: =SUM(C17:D17)/2 -> 0 | G17: =IF(E17=0," ",1/E17)
E18: =IF(G18=0," ",1/G18) | G18: =SUM(C18:D18)/2 -> 0
E19: =IF(G19=0," ",1/G19) | G19: =SUM(C19:D19)/2 -> 0
E20: =IF(G20=0," ",1/G20) | G20: =SUM(C20:D20)/2 -> 0
E21: =IF(G21=0," ",1/G21) | G21: =SUM(C21:D21)/2 -> 0
E22: =IF(G22=0," ",1/G22) | G22: =SUM(C22:D22)/2 -> 0
E23: =SUM(C23:D23)/2 -> 0 | G23: =IF(E23=0," ",1/E23)
E24: =SUM(C24:D24)/2 -> 0 | G24: =IF(E24=0," ",1/E24)

Sheet 30-0100
A1: BANK OF GHANA DAILY INTERBANK FX RATES
A2: =('07-07'!A2)+22 -> 46232
E3: USD-GHS | G3: GHS-USD
A4: Currency | B4: Pairs Code | C4: Buying | D4: Selling | E4: Average | G4: Average
A5: US Dollar | E5: =SUM(C5:D5)/2 -> 0 | G5: =IF(E5=0," ",1/E5)
A6: Pound Sterling | E6: =SUM(C6:D6)/2 -> 0 | G6: =IF(E6=0," ",1/E6)
A7: Swiss Franc | E7: =SUM(C7:D7)/2 -> 0 | G7: =IF(E7=0," ",1/E7)
A8: Australian Dollar | E8: =SUM(C8:D8)/2 -> 0 | G8: =IF(E8=0," ",1/E8)
A9: Canadian Dollar | E9: =SUM(C9:D9)/2 -> 0 | G9: =IF(E9=0," ",1/E9)
